Workbook

Sheet BRS 201506S08ZZ
B2: RELIABILITY TEST RESULT | N2: Name | O2: Maker | P2: Checker | Q2: Approval
N3: Signature
N4: Finish Date | O4: 45348 | P4: 45348 | Q4: 45348
B6: Request date | F6: 45320 | J6: Test site | N6: GN QM
B7: Product group | F7: Speaker | J7: Tester | N7: Nguyen Thi Hau
B8: Product name | F8: BRS 201506S08ZZ | J8: Department | N8: Reliability
B9: Test reason | F9: VP Plan 2 | J9: Temperature & Hummidity | N9: 26℃ / 48%
B10: Test period | F10: 30.1.2024- 26.2.2024 | J10: Sample q'ty | N10: 55EA
B11: 1. TEST ITEM AND CONDITION
B12: Test item | F12: Sample q'ty | G12: Test condition | N12: Starting date | O12: Ending date | P12: Test result | Q12: Note
B13: High temp and humidity 1 | F13: 5 | G13: Temperature: 60℃ ± 5℃, Humidity: 90% ± 5% Time: 120Hrs | N13: 45322 | O13: 45327 | P13: PASS
B14: High temp and humidity 2 | F14: 5 | G14: Temperature: 80℃ ± 5℃, Humidity: 80% ± 5% Time : 48Hrs | N14: 45325 | O14: 45327 | P14: PASS
B15: Shock temp | F15: 5 | G15: Low temperature(-40℃ ± 5℃) 30 minutes → Hight temperature (+85℃ ± 5℃) 30 minutes/1Cycle, 96 cycle | N15: 45321 | O15: 45328 | P15: PASS | Q15: Bù giờ
B16: Combine Drop test | D16: Continuously drop | F16: 5 | G16: Height:80cm, Cycle:100 times, ground:10mm Steel , JIG 300g | N16: 45322 | O16: 45322 | P16: PASS
D17: Freely drop | G17: Height:152cm, Cycle:24 times, ground:25mm Steel , JIG 300g (6 sides->4 corners->4 edges->6 sides->4 corners) | N17: 45322 | O17: 45322 | P17: PASS
B18: Load test (Max 80%) | F18: 5 | G18: White Noise (EIA Filter), at Max Power 80% (3.58Vrms) 96Hr | N18: 45322 | O18: 45326 | P18: PASS
B19: Load test (Max 100%) | F19: 5 | G19: White Noise (EIA Filter), at Max Power 100% (4.0Vrms) 96Hr | N19: 45322 | O19: 45326 | P19: PASS
B20: Load test T-Max | F20: 5 | G20: White Noise (EIA Filter 1kHz High Pass), at 4.15Vrms during 240Hr | N20: 45338 | O20: 45348 | P20: PASS
B21: Load test X-Max | F21: 5 | G21: F0:615±50Hz, at 4.3V, 5sec on 2sec off, during 240Hr | N21: 45338 | O21: 45348 | P21: PASS
B22: Combined environment operation test ( Cycle ) | F22: 10 | G22: -10℃~55℃ / 0~93%, White Noise + EIA Filter at (3.58Vrms), Time : 96Hr | N22: 45322 | O22: 45326 | P22: PASS
B23: Water Proof test | F23: 5 | G23: High : 1.5m , Time : 30 Min Wait for the goods to dry | N23: 45322 | O23: 45322 | P23: PASS
B24: ※ SPEC
B25: - Speaker: 117.4 ± 2dB at 800 ,1.kHz , 1180kHz , 1500kHz
B26: 2. TEST DATA
B27: Item | E27: SPL | H27: IMPEDANCE | K27: F0 | N27: THD
B28: STANDARD | E28: 117.4 ± 2dB | H28: 8Ω ± 15% at 2kHz (3.58V) | K28: 615 ± 120Hz at 3.58V | N28: 100-212Hz 50%300Hz 35%, 400Hz 25%, 500Hz 20%,600Hz 15%, 710Hz 12%, 800Hz 10%, 900Hz 9%,1KHz 8%, 2K~4.5KHz 5%, 5KHz 8%, 6KHz 8%,7.1-14KHz 5% with 3.58V
E29: 115.4dB - 119.4dB | H29: 6.8Ω - 9.2Ω | K29: 495Hz - 735Hz
B30: Reliability test items | D30: NO | E30: Before | F30: After | G30: Deviation | H30: Before | I30: After | J30: Deviation | K30: Before | L30: After | M30: Deviation | N30: After | O30: Deviation | P30: Before | Q30: After
B31: High temp and humidity 60 - 90 | D31: 1 | E31: ='Temp and humid 60-90'!O102 | F31: ='Temp and humid 60-90'!P102 | G31: =F31-E31 | H31: ='Temp and humid 60-90'!AM60 | I31: ='Temp and humid 60-90'!AN60 | J31: =I31-H31 | K31: ='Temp and humid 60-90'!AM102 | L31: ='Temp and humid 60-90'!AN102 | M31: =K31-L31 | N31: OK | O31: OK | P31: OK | Q31: OK
D32: 2 | E32: ='Temp and humid 60-90'!Q102 | F32: ='Temp and humid 60-90'!R102 | G32: =F32-E32 | H32: ='Temp and humid 60-90'!AO60 | I32: ='Temp and humid 60-90'!AP60 | J32: =I32-H32 | K32: ='Temp and humid 60-90'!AO102 | L32: ='Temp and humid 60-90'!AP102 | M32: =K32-L32 | N32: OK | O32: OK | P32: OK | Q32: OK
D33: 3 | E33: ='Temp and humid 60-90'!S102 | F33: ='Temp and humid 60-90'!T102 | G33: =F33-E33 | H33: ='Temp and humid 60-90'!AQ60 | I33: ='Temp and humid 60-90'!AR60 | J33: =I33-H33 | K33: ='Temp and humid 60-90'!AQ102 | L33: ='Temp and humid 60-90'!AR102 | M33: =K33-L33 | N33: OK | O33: OK | P33: OK | Q33: OK
D34: 4 | E34: ='Temp and humid 60-90'!U102 | F34: ='Temp and humid 60-90'!V102 | G34: =F34-E34 | H34: ='Temp and humid 60-90'!AS60 | I34: ='Temp and humid 60-90'!AT60 | J34: =I34-H34 | K34: ='Temp and humid 60-90'!AS102 | L34: ='Temp and humid 60-90'!AT102 | M34: =K34-L34 | N34: OK | O34: OK | P34: OK | Q34: OK
D35: 5 | E35: ='Temp and humid 60-90'!W102 | F35: ='Temp and humid 60-90'!X102 | G35: =F35-E35 | H35: ='Temp and humid 60-90'!AU60 | I35: ='Temp and humid 60-90'!AV60 | J35: =I35-H35 | K35: ='Temp and humid 60-90'!AU102 | L35: ='Temp and humid 60-90'!AV102 | M35: =K35-L35 | N35: OK | O35: OK | P35: OK | Q35: OK
B36: High temp and humidity 80 - 80 | D36: 1 | E36: ='Temp and humid 80-80'!O102 | F36: ='Temp and humid 80-80'!P102 | G36: =F36-E36 | H36: ='Temp and humid 80-80'!AM60 | I36: ='Temp and humid 80-80'!AN60 | J36: =I36-H36 | K36: ='Temp and humid 80-80'!AM102 | L36: ='Temp and humid 80-80'!AN102 | M36: =K36-L36 | N36: OK | O36: OK | P36: OK | Q36: OK
D37: 2 | E37: ='Temp and humid 80-80'!Q102 | F37: ='Temp and humid 80-80'!R102 | G37: =F37-E37 | H37: ='Temp and humid 80-80'!AO60 | I37: ='Temp and humid 80-80'!AP60 | J37: =I37-H37 | K37: ='Temp and humid 80-80'!AO102 | L37: ='Temp and humid 80-80'!AP102 | M37: =K37-L37 | N37: OK | O37: OK | P37: OK | Q37: OK
D38: 3 | E38: ='Temp and humid 80-80'!S102 | F38: ='Temp and humid 80-80'!T102 | G38: =F38-E38 | H38: ='Temp and humid 80-80'!AQ60 | I38: ='Temp and humid 80-80'!AR60 | J38: =I38-H38 | K38: ='Temp and humid 80-80'!AQ102 | L38: ='Temp and humid 80-80'!AR102 | M38: =K38-L38 | N38: OK | O38: OK | P38: OK | Q38: OK
D39: 4 | E39: ='Temp and humid 80-80'!U102 | F39: ='Temp and humid 80-80'!V102 | G39: =F39-E39 | H39: ='Temp and humid 80-80'!AS60 | I39: ='Temp and humid 80-80'!AT60 | J39: =I39-H39 | K39: ='Temp and humid 80-80'!AS102 | L39: ='Temp and humid 80-80'!AT102 | M39: =K39-L39 | N39: OK | O39: OK | P39: OK | Q39: OK
D40: 5 | E40: ='Temp and humid 80-80'!W102 | F40: ='Temp and humid 80-80'!X102 | G40: =F40-E40 | H40: ='Temp and humid 80-80'!AU60 | I40: ='Temp and humid 80-80'!AV60 | J40: =I40-H40 | K40: ='Temp and humid 80-80'!AU102 | L40: ='Temp and humid 80-80'!AV102 | M40: =K40-L40 | N40: OK | O40: OK | P40: OK | Q40: OK
B41: Shock temp | D41: 1 | E41: ='Shock temp'!O102 | F41: ='Shock temp'!P102 | G41: =F41-E41 | H41: ='Shock temp'!AM60 | I41: ='Shock temp'!AN60 | J41: =I41-H41 | K41: ='Shock temp'!AM102 | L41: ='Shock temp'!AN102 | M41: =K41-L41 | N41: OK | O41: OK | P41: OK | Q41: OK
D42: 2 | E42: ='Shock temp'!Q102 | F42: ='Shock temp'!R102 | G42: =F42-E42 | H42: ='Shock temp'!AO60 | I42: ='Shock temp'!AP60 | J42: =I42-H42 | K42: ='Shock temp'!AO102 | L42: ='Shock temp'!AP102 | M42: =K42-L42 | N42: OK | O42: OK | P42: OK | Q42: OK
...

Sheet Temp and humid 60-90
N1: SPL RAW DATA | Z1: THD RAW DATA | AL1: IMPEDANCE RAW DATA
N2: SPL specification / | S2: SPK :117.4 dB±2dB Average of frequency 0.8, 1.0, 1.2k, 1.5k, 3.58V | Z2: THD Limit / | AE2: 100-212Hz 50%300Hz 35%, 400Hz 25%, 500Hz 20%,600Hz 15%, 710Hz 12%, 800Hz 10%, 900Hz 9%,1KHz 8%, 2K~4.5KHz 5%, 5KHz 8%, 6KHz 8%,7.1-14KHz 5% with 3.58V | AL2: Imp / F0 Limit / | AQ2: IMP:8 Ω ±15% at 2kHz, 3.58V , F0: 615 ± 120Hz at 3.58V
N3: Evalution standard / | S3: Deviation before test and after test is under ± 2db, and SPL Average value in limit / | Z3: Evalution standard / | AE3: THD value in limit / | AL3: Evalution standard / | AQ3: Value in limit /
N4: Test condition / | S4: Temperature: 60℃ ± 5℃, Humidity: 90% ± 5% Time: 120Hrs | Z4: Test condition / | AE4: Temperature: 60℃ ± 5℃, Humidity: 90% ± 5% Time: 120Hrs | AL4: Test condition / | AQ4: Temperature: 60℃ ± 5℃, Humidity: 90% ± 5% Time: 120Hrs
N5: Sample No | O5: #1 | Q5: #2 | S5: #3 | U5: #4 | W5: #5 | Z5: Sample No | AA5: #1 | AC5: #2 | AE5: #3 | AG5: #4 | AI5: #5 | AL5: Sample No | AM5: #1 | AO5: #2 | AQ5: #3 | AS5: #4 | AU5: #5
N6: Result | O6: OK | P6: OK | Q6: OK | R6: OK | S6: OK | T6: OK | U6: OK | V6: OK | W6: OK | X6: OK | AM6: OK | AN6: OK | AO6: OK | AP6: OK | AQ6: OK | AR6: OK | AS6: OK | AT6: OK | AU6: OK | AV6: OK
O7: Before #1 | P7: After #1 | Q7: Before #2 | R7: After #2 | S7: Before #3 | T7: After #3 | U7: Before #4 | V7: After #4 | W7: Before #5 | X7: After #5 | AA7: Before #1 | AB7: After #1 | AC7: Before #2 | AD7: After #2 | AE7: Before #3 | AF7: After #3 | AG7: Before #4 | AH7: After #4 | AI7: Before #5 | AJ7: After #5 | AM7: Before #1 | AN7: After #1 | AO7: Before #2 | AP7: After #2 | AQ7: Before #3 | AR7: After #3 | AS7: Before #4 | AT7: After #4 | AU7: Before #5 | AV7: After #5
N8: 100 | O8: 79.0422 | P8: 79.27731 | Q8: 79.281 | R8: 79.58975 | S8: 79.62009 | T8: 79.33194 | U8: 79.21218 | V8: 79.22018 | W8: 79.07808 | X8: 79.05526 | Z8: 100 | AA8: 23.2127 | AB8: 21.36478 | AC8: 24.2676 | AD8: 25.49907 | AE8: 23.84795 | AF8: 23.98408 | AG8: 19.79098 | AH8: 24.56962 | AI8: 23.53371 | AJ8: 23.53708 | AL8: 100 | AM8: 6.41133 | AN8: 6.52697 | AO8: 6.43816 | AP8: 6.51791 | AQ8: 6.4194 | AR8: 6.51346 | AS8: 6.39946 | AT8: 6.52181 | AU8: 6.40281 | AV8: 6.52638
N9: 106 | O9: 79.45589 | P9: 79.68135 | Q9: 79.65477 | R9: 80.02742 | S9: 79.96398 | T9: 79.75045 | U9: 79.62985 | V9: 79.62488 | W9: 79.49956 | X9: 79.47237 | Z9: 106 | AA9: 23.25314 | AB9: 21.47439 | AC9: 24.24057 | AD9: 25.62707 | AE9: 24.13283 | AF9: 24.1272 | AG9: 19.96895 | AH9: 24.76546 | AI9: 23.83349 | AJ9: 23.66767 | AL9: 106 | AM9: 6.47791 | AN9: 6.5946 | AO9: 6.50398 | AP9: 6.58529 | AQ9: 6.48767 | AR9: 6.57826 | AS9: 6.46575 | AT9: 6.58785 | AU9: 6.47101 | AV9: 6.59203
N10: 112 | O10: 79.94698 | P10: 80.17292 | Q10: 80.10009 | R10: 80.52905 | S10: 80.38305 | T10: 80.24657 | U10: 80.13179 | V10: 80.12352 | W10: 79.99517 | X10: 79.96906 | Z10: 112 | AA10: 23.34859 | AB10: 21.59661 | AC10: 24.24103 | AD10: 25.94492 | AE10: 24.45106 | AF10: 24.28545 | AG10: 20.12043 | AH10: 24.90783 | AI10: 24.11766 | AJ10: 23.81323 | AL10: 112 | AM10: 6.53173 | AN10: 6.64817 | AO10: 6.55667 | AP10: 6.63779 | AQ10: 6.54094 | AR10: 6.63026 | AS10: 6.51825 | AT10: 6.64165 | AU10: 6.52527 | AV10: 6.64469
N11: 118 | O11: 80.82054 | P11: 81.08137 | Q11: 80.93458 | R11: 81.40868 | S11: 81.15616 | T11: 81.1629 | U11: 81.04854 | V11: 81.04827 | W11: 80.91136 | X11: 80.88754 | Z11: 118 | AA11: 23.5172 | AB11: 21.6884 | AC11: 24.29091 | AD11: 26.1227 | AE11: 24.78706 | AF11: 24.45829 | AG11: 20.30926 | AH11: 25.07981 | AI11: 24.43374 | AJ11: 24.01738 | AL11: 118 | AM11: 6.5755 | AN11: 6.69303 | AO11: 6.60157 | AP11: 6.68105 | AQ11: 6.58507 | AR11: 6.67412 | AS11: 6.56179 | AT11: 6.68583 | AU11: 6.5696 | AV11: 6.68901
N12: 125 | O12: 81.81944 | P12: 82.10406 | Q12: 81.87931 | R12: 82.43469 | S12: 82.05198 | T12: 82.17289 | U12: 82.07052 | V12: 82.06511 | W12: 81.94412 | X12: 81.89985 | Z12: 125 | AA12: 23.67615 | AB12: 21.84574 | AC12: 24.39931 | AD12: 26.39471 | AE12: 25.21965 | AF12: 24.72928 | AG12: 20.55296 | AH12: 25.29758 | AI12: 24.83949 | AJ12: 24.23573 | AL12: 125 | AM12: 6.61876 | AN12: 6.73652 | AO12: 6.64428 | AP12: 6.72452 | AQ12: 6.62937 | AR12: 6.71768 | AS12: 6.60519 | AT12: 6.72863 | AU12: 6.61174 | AV12: 6.7334
N13: 132 | O13: 82.89711 | P13: 83.22584 | Q13: 82.94504 | R13: 83.54043 | S13: 83.04239 | T13: 83.26759 | U13: 83.21302 | V13: 83.18185 | W13: 83.07913 | X13: 83.03065 | Z13: 132 | AA13: 24.14729 | AB13: 22.14105 | AC13: 24.7547 | AD13: 26.94896 | AE13: 26.04987 | AF13: 25.2307 | AG13: 21.07443 | AH13: 25.76644 | AI13: 25.60746 | AJ13: 24.69105 | AL13: 132 | AM13: 6.6541 | AN13: 6.77323 | AO13: 6.68081 | AP13: 6.76041 | AQ13: 6.66586 | AR13: 6.7536 | AS13: 6.64116 | AT13: 6.76481 | AU13: 6.64673 | AV13: 6.77011
N14: 140 | O14: 84.02163 | P14: 84.50209 | Q14: 84.02903 | R14: 84.7719 | S14: 84.06067 | T14: 84.48727 | U14: 84.4294 | V14: 84.41459 | W14: 84.28938 | X14: 84.27426 | Z14: 140 | AA14: 24.84959 | AB14: 22.454 | AC14: 25.38077 | AD14: 27.49564 | AE14: 27.02624 | AF14: 25.81282 | AG14: 21.73689 | AH14: 26.26481 | AI14: 26.49128 | AJ14: 25.17645 | AL14: 140 | AM14: 6.68831 | AN14: 6.80932 | AO14: 6.71799 | AP14: 6.7961 | AQ14: 6.70175 | AR14: 6.78889 | AS14: 6.67701 | AT14: 6.79992 | AU14: 6.68161 | AV14: 6.80556
N15: 150 | O15: 85.13968 | P15: 85.85266 | Q15: 85.07303 | R15: 86.0578 | S15: 84.99425 | T15: 85.75983 | U15: 85.65252 | V15: 85.6925 | W15: 85.51457 | X15: 85.56605 | Z15: 150 | AA15: 25.11849 | AB15: 22.6772 | AC15: 25.4847 | AD15: 27.78827 | AE15: 27.93755 | AF15: 26.20539 | AG15: 22.45434 | AH15: 26.56745 | AI15: 27.30621 | AJ15: 25.50662 | AL15: 150 | AM15: 6.72587 | AN15: 6.84734 | AO15: 6.75686 | AP15: 6.83292 | AQ15: 6.74095 | AR15: 6.8278 | AS15: 6.71568 | AT15: 6.83717 | AU15: 6.71919 | AV15: 6.84432
N16: 160 | O16: 86.28645 | P16: 87.26189 | Q16: 86.13167 | R16: 87.41593 | S16: 85.92993 | T16: 87.06564 | U16: 86.88101 | V16: 86.99973 | W16: 86.73671 | X16: 86.88863 | Z16: 160 | AA16: 24.56301 | AB16: 22.645 | AC16: 24.64345 | AD16: 27.63996 | AE16: 28.30072 | AF16: 26.27636 | AG16: 22.86194 | AH16: 26.56787 | AI16: 27.58532 | AJ16: 25.39904 | AL16: 160 | AM16: 6.75937 | AN16: 6.88049 | AO16: 6.79065 | AP16: 6.8658 | AQ16: 6.77518 | AR16: 6.86145 | AS16: 6.74814 | AT16: 6.86983 | AU16: 6.75228 | AV16: 6.87787
N17: 170 | O17: 87.68844 | P17: 88.76678 | Q17: 87.59251 | R17: 88.86886 | S17: 87.34681 | T17: 88.50013 | U17: 88.21032 | V17: 88.39349 | W17: 88.06273 | X17: 88.28101 | Z17: 170 | AA17: 24.05275 | AB17: 22.59633 | AC17: 23.95627 | AD17: 27.41538 | AE17: 28.64244 | AF17: 26.35421 | AG17: 23.28152 | AH17: 26.58904 | AI17: 27.88712 | AJ17: 25.30905 | AL17: 170 | AM17: 6.7882 | AN17: 6.90938 | AO17: 6.81969 | AP17: 6.89507 | AQ17: 6.80451 | AR17: 6.89104 | AS17: 6.77643 | AT17: 6.89726 | AU17: 6.78142 | AV17: 6.90878
N18: 180 | O18: 89.43966 | P18: 90.31802 | Q18: 89.51339 | R18: 90.44867 | S18: 89.32661 | T18: 90.09597 | U18: 89.70297 | V18: 89.88993 | W18: 89.55167 | X18: 89.75629 | Z18: 180 | AA18: 23.59448 | AB18: 22.44917 | AC18: 23.25631 | AD18: 27.08442 | AE18: 28.82814 | AF18: 26.34363 | AG18: 23.56225 | AH18: 26.4524 | AI18: 28.04654 | AJ18: 25.08638 | AL18: 180 | AM18: 6.81219 | AN18: 6.93568 | AO18: 6.84536 | AP18: 6.92075 | AQ18: 6.83002 | AR18: 6.91718 | AS18: 6.80065 | AT18: 6.92265 | AU18: 6.80635 | AV18: 6.9358
L19: Limit | N19: 190 | O19: 90.92792 | P19: 91.69424 | Q19: 91.08206 | R19: 91.87976 | S19: 90.91474 | T19: 91.54151 | U19: 91.08233 | V19: 91.30811 | W19: 90.9245 | X19: 91.1677 | Z19: 190 | AA19: 23.00083 | AB19: 22.10859 | AC19: 22.51993 | AD19: 26.53062 | AE19: 28.74962 | AF19: 26.16521 | AG19: 23.62032 | AH19: 26.0625 | AI19: 28.00425 | AJ19: 24.63557 | AL19: 190 | AM19: 6.83426 | AN19: 6.95894 | AO19: 6.8681 | AP19: 6.9447 | AQ19: 6.8532 | AR19: 6.94046 | AS19: 6.82263 | AT19: 6.94591 | AU19: 6.82917 | AV19: 6.95981
K20: 100 | L20: 50 | N20: 200 | O20: 92.3077 | P20: 92.95932 | Q20: 92.53041 | R20: 93.17392 | S20: 92.38603 | T20: 92.84977 | U20: 92.38822 | V20: 92.60763 | W20: 92.23555 | X20: 92.4455 | Z20: 200 | AA20: 22.14472 | AB20: 21.61462 | AC20: 21.7115 | AD20: 25.89295 | AE20: 28.36921 | AF20: 25.7982 | AG20: 23.44895 | AH20: 25.47096 | AI20: 27.70743 | AJ20: 23.97732 | AL20: 200 | AM20: 6.85387 | AN20: 6.98038 | AO20: 6.8896 | AP20: 6.96656 | AQ20: 6.87513 | AR20: 6.96195 | AS20: 6.84373 | AT20: 6.96762 | AU20: 6.84934 | AV20: 6.98185
K21: 212 | L21: 50 | N21: 212 | O21: 93.58648 | P21: 94.12671 | Q21: 93.8437 | R21: 94.3766 | S21: 93.71432 | T21: 94.07179 | U21: 93.62222 | V21: 93.83418 | W21: 93.48402 | X21: 93.65552 | Z21: 212 | AA21: 20.95598 | AB21: 20.74994 | AC21: 20.57466 | AD21: 24.82333 | AE21: 27.49608 | AF21: 25.02829 | AG21: 22.91767 | AH21: 24.49781 | AI21: 26.97657 | AJ21: 22.99054 | AL21: 212 | AM21: 6.87696 | AN21: 7.00494 | AO21: 6.9149 | AP21: 6.99121 | AQ21: 6.8986 | AR21: 6.98612 | AS21: 6.86756 | AT21: 6.99236 | AU21: 6.87231 | AV21: 7.00671
K22: 300 | L22: 35 | N22: 224 | O22: 94.72639 | P22: 95.20502 | Q22: 94.955 | R22: 95.47466 | S22: 94.80962 | T22: 95.17825 | U22: 94.79826 | V22: 94.97392 | W22: 94.64877 | X22: 94.78425 | Z22: 224 | AA22: 19.53753 | AB22: 19.76727 | AC22: 19.20201 | AD22: 23.48905 | AE22: 26.27432 | AF22: 24.01534 | AG22: 22.1668 | AH22: 23.29656 | AI22: 25.93915 | AJ22: 21.83406 | AL22: 224 | AM22: 6.89771 | AN22: 7.02738 | AO22: 6.93856 | AP22: 7.01452 | AQ22: 6.92074 | AR22: 7.00927 | AS22: 6.89007 | AT22: 7.01527 | AU22: 6.89466 | AV22: 7.02954
K23: 400 | L23: 25 | N23: 236 | O23: 95.7015 | P23: 96.23104 | Q23: 95.84678 | R23: 96.49035 | S23: 95.64216 | T23: 96.17953 | U23: 95.88194 | V23: 96.01752 | W23: 95.73085 | X23: 95.82696 | Z23: 236 | AA23: 17.83515 | AB23: 18.5604 | AC23: 17.48905 | AD23: 21.9005 | AE23: 24.73886 | AF23: 22.6736 | AG23: 21.14751 | AH23: 21.85411 | AI23: 24.60492 | AJ23: 20.41191 | AL23: 236 | AM23: 6.91875 | AN23: 7.04954 | AO23: 6.96094 | AP23: 7.03822 | AQ23: 6.94259 | AR23: 7.03087 | AS23: 6.9114 | AT23: 7.03747 | AU23: 6.91609 | AV23: 7.0524
K24: 500 | L24: 20 | N24: 250 | O24: 96.75818 | P24: 97.2944 | Q24: 96.86116 | R24: 97.53127 | S24: 96.61614 | T24: 97.21094 | U24: 96.98671 | V24: 97.05782 | W24: 96.83251 | X24: 96.86104 | Z24: 250 | AA24: 16.21307 | AB24: 17.15391 | AC24: 16.04231 | AD24: 20.08242 | AE24: 22.91534 | AF24: 21.08011 | AG24: 19.88048 | AH24: 20.16721 | AI24: 23.01697 | AJ24: 18.75568 | AL24: 250 | AM24: 6.94329 | AN24: 7.07482 | AO24: 6.98596 | AP24: 7.06491 | AQ24: 6.967 | AR24: 7.05649 | AS24: 6.9348 | AT24: 7.06407 | AU24: 6.93967 | AV24: 7.0794
K25: 600 | L25: 15 | N25: 265 | O25: 97.93228 | P25: 98.49104 | Q25: 98.00576 | R25: 98.71848 | S25: 97.72853 | T25: 98.39121 | U25: 98.19986 | V25: 98.23571 | W25: 98.03224 | X25: 98.04604 | Z25: 265 | AA25: 15.19126 | AB25: 15.85643 | AC25: 15.38348 | AD25: 18.47451 | AE25: 21.28566 | AF25: 19.56884 | AG25: 18.69513 | AH25: 18.48494 | AI25: 21.61012 | AJ25: 17.2534 | AL25: 265 | AM25: 6.96925 | AN25: 7.1021 | AO25: 7.01308 | AP25: 7.09294 | AQ25: 6.99371 | AR25: 7.08256 | AS25: 6.96036 | AT25: 7.0916 | AU25: 6.96605 | AV25: 7.10851
K26: 710 | L26: 12 | N26: 280 | O26: 99.1326 | P26: 99.70127 | Q26: 99.18578 | R26: 99.91931 | S26: 98.88218 | T26: 99.58743 | U26: 99.41954 | V26: 99.42268 | W26: 99.23237 | X26: 99.23506 | Z26: 280 | AA26: 14.11169 | AB26: 14.59798 | AC26: 14.75167 | AD26: 16.9721 | AE26: 19.61897 | AF26: 18.03776 | AG26: 17.42689 | AH26: 16.80669 | AI26: 20.168 | AJ26: 15.81051 | AL26: 280 | AM26: 6.99635 | AN26: 7.13092 | AO26: 7.04142 | AP26: 7.12252 | AQ26: 7.02107 | AR26: 7.11019 | AS26: 6.98716 | AT26: 7.12106 | AU26: 6.99283 | AV26: 7.13955
K27: 800 | L27: 10 | N27: 300 | O27: 100.39912 | P27: 100.99198 | Q27: 100.43207 | R27: 101.20479 | S27: 100.09915 | T27: 100.87083 | U27: 100.70094 | V27: 100.69461 | W27: 100.50302 | X27: 100.50765 | Z27: 300 | AA27: 12.7704 | AB27: 13.06458 | AC27: 14.03068 | AD27: 15.06805 | AE27: 17.50557 | AF27: 16.08271 | AG27: 15.84503 | AH27: 14.78678 | AI27: 18.27696 | AJ27: 14.0573 | AL27: 300 | AM27: 7.0322 | AN27: 7.17109 | AO27: 7.0805 | AP27: 7.16501 | AQ27: 7.05992 | AR27: 7.1508 | AS27: 7.02348 | AT27: 7.16175 | AU27: 7.03069 | AV27: 7.18399
K28: 900 | L28: 9 | N28: 315 | O28: 101.67768 | P28: 102.30121 | Q28: 101.69209 | R28: 102.50301 | S28: 101.32638 | T28: 102.17158 | U28: 102.00216 | V28: 101.99598 | W28: 101.79012 | X28: 101.80852 | Z28: 315 | AA28: 11.81657 | AB28: 12.09568 | AC28: 13.51995 | AD28: 13.77124 | AE28: 16.07159 | AF28: 14.72039 | AG28: 14.81151 | AH28: 13.55143 | AI28: 16.94641 | AJ28: 12.93644 | AL28: 315 | AM28: 7.06185 | AN28: 7.20376 | AO28: 7.11194 | AP28: 7.19913 | AQ28: 7.09194 | AR28: 7.18248 | AS28: 7.05429 | AT28: 7.1955 | AU28: 7.06024 | AV28: 7.22053
K29: 1000 | L29: 8 | N29: 335 | O29: 102.95788 | P29: 103.6044 | Q29: 102.95053 | R29: 103.79431 | S29: 102.55083 | T29: 103.46425 | U29: 103.30535 | V29: 103.2914 | W29: 103.08252 | X29: 103.10397 | Z29: 335 | AA29: 10.83935 | AB29: 11.01041 | AC29: 12.8599 | AD29: 12.26466 | AE29: 14.46397 | AF29: 13.09031 | AG29: 13.61459 | AH29: 12.14243 | AI29: 15.3449 | AJ29: 11.65429 | AL29: 335 | AM29: 7.10432 | AN29: 7.25025 | AO29: 7.15772 | AP29: 7.24987 | AQ29: 7.13797 | AR29: 7.22848 | AS29: 7.09731 | AT29: 7.24354 | AU29: 7.10436 | AV29: 7.27353
K30: 2000 | L30: 5 | N30: 355 | O30: 104.25795 | P30: 104.91825 | Q30: 104.22676 | R30: 105.08971 | S30: 103.77711 | T30: 104.76061 | U30: 104.63229 | V30: 104.59528 | W30: 104.39832 | X30: 104.40825 | Z30: 355 | AA30: 10.03922 | AB30: 10.16497 | AC30: 12.26654 | AD30: 11.02939 | AE30: 13.15952 | AF30: 11.67783 | AG30: 12.62536 | AH30: 10.98584 | AI30: 13.97066 | AJ30: 10.56291 | AL30: 355 | AM30: 7.15184 | AN30: 7.30343 | AO30: 7.20851 | AP30: 7.30772 | AQ30: 7.19038 | AR30: 7.28062 | AS30: 7.14639 | AT30: 7.29991 | AU30: 7.1546 | AV30: 7.33489
K31: 4500 | L31: 5 | N31: 375 | O31: 105.60523 | P31: 106.26366 | Q31: 105.53982 | R31: 106.40347 | S31: 105.03781 | T31: 106.08166 | U31: 106.00159 | V31: 105.93169 | W31: 105.75982 | X31: 105.74982 | Z31: 375 | AA31: 9.36533 | AB31: 9.53705 | AC31: 11.76603 | AD31: 10.08555 | AE31: 12.1433 | AF31: 10.53075 | AG31: 11.77169 | AH31: 10.07474 | AI31: 12.84533 | AJ31: 9.64913 | AL31: 375 | AM31: 7.2059 | AN31: 7.36512 | AO31: 7.26465 | AP31: 7.37443 | AQ31: 7.25108 | AR31: 7.34101 | AS31: 7.20175 | AT31: 7.36389 | AU31: 7.21192 | AV31: 7.40361
... K35: 14000 | L35: 5 | N35: 475 | O35: 110.6923 | P35: 111.29553 | Q35: 110.46813 | R35: 111.20195 | S35: 109.8168 | T35: 110.99475 | U35: 110.94327 | V35: 110.93897 | W35: 110.8639 | X35: 110.76518 | Z35: 475 | AA35: 7.51506 | AB35: 8.14017 | AC35: 9.76927 | AD35: 8.04462 | AE35: 9.47325 | AF35: 7.57405 | AG35: 8.99738 | AH35: 7.97955 | AI35: 9.62454 | AJ35: 7.42241 | AL35: 475 | AM35: 7.62077 | AN35: 7.817 | AO35: 7.67181 | AP35: 7.83839 | AQ35: 7.72714 | AR35: 7.78415 | AS35: 7.62959 | AT35: 7.85407 | AU35: 7.66757 | AV35: 7.89923
N36: 500 | O36: 111.85523 | P36: 112.43095 | Q36: 111.58566 | R36: 112.2776 | S36: 110.90143 | T36: 112.10754 | U36: 112.03169 | V36: 112.07589 | W36: 112.0251 | X36: 111.90785 | Z36: 500 | AA36: 7.05775 | AB36: 7.80622 | AC36: 9.13978 | AD36: 7.57929 | AE36: 8.85517 | AF36: 6.99916 | AG36: 8.41042 | AH36: 7.54127 | AI36: 8.8896 | AJ36: 6.98963 | AL36: 500 | AM36: 7.75861 | AN36: 7.94933 | AO36: 7.79739 | AP36: 7.96294 | AQ36: 7.87062 | AR36: 7.92916 | AS36: 7.77378 | AT36: 8.01511 | AU36: 7.8087 | AV36: 8.04622
N37: 530 | O37: 112.98473 | P37: 113.53517 | Q37: 112.66526 | R37: 113.33303 | S37: 111.92686 | T37: 113.19192 | U37: 113.14095 | V37: 113.1886 | W37: 113.16775 | X37: 113.04195 | Z37: 530 | AA37: 6.55521 | AB37: 7.38402 | AC37: 8.34 | AD37: 7.04407 | AE37: 8.16676 | AF37: 6.39778 | AG37: 7.75916 | AH37: 7.00157 | AI37: 8.0931 | AJ37: 6.50028 | AL37: 530 | AM37: 7.92731 | AN37: 8.0877 | AO37: 7.94571 | AP37: 8.11021 | AQ37: 8.02162 | AR37: 8.10373 | AS37: 7.95722 | AT37: 8.20938 | AU37: 7.95675 | AV37: 8.22223
N38: 560 | O38: 114.00183 | P38: 114.51632 | Q38: 113.63433 | R38: 114.28584 | S38: 112.87017 | T38: 114.16648 | U38: 114.16763 | V38: 114.18705 | W38: 114.19409 | X38: 114.0666 | Z38: 560 | AA38: 6.14458 | AB38: 7.03154 | AC38: 7.67499 | AD38: 6.59779 | AE38: 7.57244 | AF38: 5.93631 | AG38: 7.22701 | AH38: 6.55138 | AI38: 7.44943 | AJ38: 6.1064 | AL38: 560 | AM38: 8.07886 | AN38: 8.21473 | AO38: 8.07829 | AP38: 8.25248 | AQ38: 8.16952 | AR38: 8.26856 | AS38: 8.13003 | AT38: 8.3845 | AU38: 8.08969 | AV38: 8.3822
N39: 600 | O39: 114.92891 | P39: 115.40664 | Q39: 114.5333 | R39: 115.17578 | S39: 113.7937 | T39: 115.06529 | U39: 115.1404 | V39: 115.10451 | W39: 115.137 | X39: 115.02107 | Z39: 600 | AA39: 5.75426 | AB39: 6.65084 | AC39: 7.00039 | AD39: 6.10564 | AE39: 6.92498 | AF39: 5.50183 | AG39: 6.70145 | AH39: 6.07071 | AI39: 6.80197 | AJ39: 5.74317 | AL39: 600 | AM39: 8.24972 | AN39: 8.37274 | AO39: 8.21083 | AP39: 8.38746 | AQ39: 8.33978 | AR39: 8.44532 | AS39: 8.30288 | AT39: 8.54279 | AU39: 8.25333 | AV39: 8.53037
N40: 630 | O40: 115.72134 | P40: 116.16106 | Q40: 115.33749 | R40: 115.94587 | S40: 114.65859 | T40: 115.84394 | U40: 116.00152 | V40: 115.89446 | W40: 115.94806 | X40: 115.8526 | Z40: 630 | AA40: 5.52419 | AB40: 6.39424 | AC40: 6.58153 | AD40: 5.77257 | AE40: 6.4863 | AF40: 5.24051 | AG40: 6.38091 | AH40: 5.76126 | AI40: 6.39014 | AJ40: 5.53807 | AL40: 630 | AM40: 8.34485 | AN40: 8.45617 | AO40: 8.273 | AP40: 8.43904 | AQ40: 8.42548 | AR40: 8.52743 | AS40: 8.37648 | AT40: 8.59829 | AU40: 8.3446 | AV40: 8.58506
N41: 670 | O41: 116.38745 | P41: 116.80304 | Q41: 116.08341 | R41: 116.62083 | S41: 115.49727 | T41: 116.52437 | U41: 116.72366 | V41: 116.57623 | W41: 116.62558 | X41: 116.5741 | Z41: 670 | AA41: 5.1835 | AB41: 6.03686 | AC41: 6.03764 | AD41: 5.30291 | AE41: 5.86796 | AF41: 4.89356 | AG41: 5.97713 | AH41: 5.3435 | AI41: 5.82782 | AJ41: 5.26344 | AL41: 670 | AM41: 8.38155 | AN41: 8.48514 | AO41: 8.29001 | AP41: 8.42812 | AQ41: 8.42521 | AR41: 8.53702 | AS41: 8.37038 | AT41: 8.56309 | AU41: 8.36837 | AV41: 8.56525
N42: 710 | O42: 116.89411 | P42: 117.29374 | Q42: 116.71629 | R42: 117.14547 | S42: 116.2436 | T42: 117.05832 | U42: 117.25218 | V42: 117.11211 | W42: 117.13223 | X42: 117.13983 | Z42: 710 | AA42: 4.80608 | AB42: 5.62897 | AC42: 5.54786 | AD42: 4.83627 | AE42: 5.27752 | AF42: 4.55993 | AG42: 5.57069 | AH42: 4.93862 | AI42: 5.24866 | AJ42: 4.97034 | AL42: 710 | AM42: 8.32427 | AN42: 8.42316 | AO42: 8.23993 | AP42: 8.33509 | AQ42: 8.32427 | AR42: 8.4512 | AS42: 8.27335 | AT42: 8.44061 | AU42: 8.29395 | AV42: 8.45497
N43: 750 | O43: 117.24093 | P43: 117.62329 | Q43: 117.20035 | R43: 117.50886 | S43: 116.83319 | T43: 117.43045 | U43: 117.59644 | V43: 117.48526 | W43: 117.47406 | X43: 117.53833 | Z43: 750 | AA43: 4.44265 | AB43: 5.20792 | AC43: 5.11502 | AD43: 4.46599 | AE43: 4.79025 | AF43: 4.25165 | AG43: 5.18083 | AH43: 4.55936 | AI43: 4.76523 | AJ43: 4.67535 | AL43: 750 | AM43: 8.19314 | AN43: 8.2901 | AO43: 8.1348 | AP43: 8.18037 | AQ43: 8.15751 | AR43: 8.29988 | AS43: 8.12025 | AT43: 8.26383 | AU43: 8.15038 | AV43: 8.28351
...

Sheet Temp and humid 80-80
N1: SPL RAW DATA | Z1: THD RAW DATA | AL1: IMPEDANCE RAW DATA
N2: SPL specification / | S2: SPK :117.4 dB±2dB Average of frequency 0.8, 1.0, 1.2k, 1.5k, 3.58V | Z2: THD Limit / | AE2: 100-212Hz 50%300Hz 35%, 400Hz 25%, 500Hz 20%,600Hz 15%, 710Hz 12%, 800Hz 10%, 900Hz 9%,1KHz 8%, 2K~4.5KHz 5%, 5KHz 8%, 6KHz 8%,7.1-14KHz 5% with 3.58V | AL2: Imp / F0 Limit / | AQ2: IMP:8 Ω ±15% at 2kHz, 3.58V , F0: 615 ± 120Hz at 3.58V
N3: Evalution standard / | S3: Deviation before test and after test is under ± 2db, and SPL Average value in limit / | Z3: Evalution standard / | AE3: THD value in limit / | AL3: Evalution standard / | AQ3: Value in limit /
N4: Test condition / | S4: Temperature: 80℃ ± 5℃, Humidity: 80% ± 5% Time : 48Hrs | Z4: Test condition / | AE4: Temperature: 80℃ ± 5℃, Humidity: 80% ± 5% Time : 48Hrs | AL4: Test condition / | AQ4: Temperature: 80℃ ± 5℃, Humidity: 80% ± 5% Time : 48Hrs
N5: Sample No | O5: #1 | Q5: #2 | S5: #3 | U5: #4 | W5: #5 | Z5: Sample No | AA5: #1 | AC5: #2 | AE5: #3 | AG5: #4 | AI5: #5 | AL5: Sample No | AM5: #1 | AO5: #2 | AQ5: #3 | AS5: #4 | AU5: #5
N6: Result | O6: OK | P6: OK | Q6: OK | R6: OK | S6: OK | T6: OK | U6: OK | V6: OK | W6: OK | X6: OK | AM6: OK | AN6: OK | AO6: OK | AP6: OK | AQ6: OK | AR6: OK | AS6: OK | AT6: OK | AU6: OK | AV6: OK
O7: Before #1 | P7: After #1 | Q7: Before #2 | R7: After #2 | S7: Before #3 | T7: After #3 | U7: Before #4 | V7: After #4 | W7: Before #5 | X7: After #5 | AA7: Before #1 | AB7: After #1 | AC7: Before #2 | AD7: After #2 | AE7: Before #3 | AF7: After #3 | AG7: Before #4 | AH7: After #4 | AI7: Before #5 | AJ7: After #5 | AM7: Before #1 | AN7: After #1 | AO7: Before #2 | AP7: After #2 | AQ7: Before #3 | AR7: After #3 | AS7: Before #4 | AT7: After #4 | AU7: Before #5 | AV7: After #5
N8: 100 | O8: 78.98888 | P8: 78.90842 | Q8: 79.32623 | R8: 79.11903 | S8: 79.3328 | T8: 79.14921 | U8: 78.63066 | V8: 79.0918 | W8: 78.73214 | X8: 79.03436 | Z8: 100 | AA8: 20.93135 | AB8: 22.27565 | AC8: 22.09387 | AD8: 22.75693 | AE8: 19.61488 | AF8: 24.06321 | AG8: 20.38741 | AH8: 24.55303 | AI8: 21.66092 | AJ8: 21.5597 | AL8: 100 | AM8: 6.42635 | AN8: 6.53257 | AO8: 6.39598 | AP8: 6.56008 | AQ8: 6.40114 | AR8: 6.53107 | AS8: 6.46715 | AT8: 6.50707 | AU8: 6.39761 | AV8: 6.51602
N9: 106 | O9: 79.39866 | P9: 79.33308 | Q9: 79.75002 | R9: 79.49331 | S9: 79.75972 | T9: 79.54455 | U9: 79.04375 | V9: 79.53464 | W9: 79.16774 | X9: 79.4415 | Z9: 106 | AA9: 21.09362 | AB9: 22.29775 | AC9: 22.36238 | AD9: 22.93957 | AE9: 19.74176 | AF9: 24.20701 | AG9: 20.54813 | AH9: 24.74509 | AI9: 21.87274 | AJ9: 21.72821 | AL9: 106 | AM9: 6.4943 | AN9: 6.59949 | AO9: 6.46413 | AP9: 6.62827 | AQ9: 6.46751 | AR9: 6.59679 | AS9: 6.53378 | AT9: 6.57152 | AU9: 6.46641 | AV9: 6.58355
N10: 112 | O10: 79.92389 | P10: 79.837 | Q10: 80.2519 | R10: 79.9755 | S10: 80.25316 | T10: 80.05371 | U10: 79.54602 | V10: 80.02747 | W10: 79.65722 | X10: 79.94189 | Z10: 112 | AA10: 21.19315 | AB10: 22.35046 | AC10: 22.61274 | AD10: 23.08955 | AE10: 19.88511 | AF10: 24.35685 | AG10: 20.67314 | AH10: 24.88049 | AI10: 22.22293 | AJ10: 21.89094 | AL10: 112 | AM10: 6.54675 | AN10: 6.6526 | AO10: 6.51593 | AP10: 6.68334 | AQ10: 6.51927 | AR10: 6.65001 | AS10: 6.58758 | AT10: 6.62547 | AU10: 6.5202 | AV10: 6.63554
N11: 118 | O11: 80.82752 | P11: 80.77945 | Q11: 81.15675 | R11: 80.84147 | S11: 81.16174 | T11: 80.96267 | U11: 80.45816 | V11: 80.94514 | W11: 80.57664 | X11: 80.87589 | Z11: 118 | AA11: 21.35102 | AB11: 22.43805 | AC11: 22.88605 | AD11: 23.25153 | AE11: 20.06197 | AF11: 24.53171 | AG11: 20.87088 | AH11: 25.07627 | AI11: 22.47379 | AJ11: 22.06689 | AL11: 118 | AM11: 6.59098 | AN11: 6.6958 | AO11: 6.56014 | AP11: 6.72793 | AQ11: 6.56247 | AR11: 6.69401 | AS11: 6.63287 | AT11: 6.66989 | AU11: 6.56438 | AV11: 6.67973
N12: 125 | O12: 81.8583 | P12: 81.8197 | Q12: 82.20892 | R12: 81.84592 | S12: 82.18148 | T12: 81.97518 | U12: 81.48789 | V12: 81.9541 | W12: 81.62806 | X12: 81.87955 | Z12: 125 | AA12: 21.54798 | AB12: 22.53396 | AC12: 23.22304 | AD12: 23.41915 | AE12: 20.262 | AF12: 24.71663 | AG12: 21.11821 | AH12: 25.21999 | AI12: 22.76596 | AJ12: 22.28897 | AL12: 125 | AM12: 6.63354 | AN12: 6.73856 | AO12: 6.6039 | AP12: 6.77112 | AQ12: 6.60578 | AR12: 6.73804 | AS12: 6.67524 | AT12: 6.71308 | AU12: 6.60764 | AV12: 6.72374
N13: 132 | O13: 82.98932 | P13: 82.94394 | Q13: 83.35286 | R13: 82.95105 | S13: 83.31207 | T13: 83.08306 | U13: 82.60947 | V13: 83.04596 | W13: 82.76321 | X13: 82.99519 | Z13: 132 | AA13: 22.0169 | AB13: 22.78878 | AC13: 23.91475 | AD13: 23.7972 | AE13: 20.69724 | AF13: 25.17782 | AG13: 21.6197 | AH13: 25.64595 | AI13: 23.41995 | AJ13: 22.72756 | AL13: 132 | AM13: 6.67008 | AN13: 6.77496 | AO13: 6.63996 | AP13: 6.80715 | AQ13: 6.64155 | AR13: 6.77466 | AS13: 6.71197 | AT13: 6.74897 | AU13: 6.64396 | AV13: 6.7599
N14: 140 | O14: 84.20038 | P14: 84.17472 | Q14: 84.56286 | R14: 84.20349 | S14: 84.51431 | T14: 84.31838 | U14: 83.82125 | V14: 84.24185 | W14: 83.96305 | X14: 84.23697 | Z14: 140 | AA14: 22.58953 | AB14: 23.08551 | AC14: 24.72782 | AD14: 24.24145 | AE14: 21.2622 | AF14: 25.68217 | AG14: 22.26905 | AH14: 26.00435 | AI14: 24.1688 | AJ14: 23.24851 | AL14: 140 | AM14: 6.70532 | AN14: 6.8098 | AO14: 6.67538 | AP14: 6.84311 | AQ14: 6.67643 | AR14: 6.80929 | AS14: 6.74884 | AT14: 6.78458 | AU14: 6.67908 | AV14: 6.79572
N15: 150 | O15: 85.41677 | P15: 85.45437 | Q15: 85.78511 | R15: 85.50942 | S15: 85.72963 | T15: 85.58816 | U15: 85.02374 | V15: 85.50019 | W15: 85.18623 | X15: 85.53807 | Z15: 150 | AA15: 23.07599 | AB15: 23.26445 | AC15: 25.49835 | AD15: 24.55785 | AE15: 21.85946 | AF15: 26.00578 | AG15: 22.91595 | AH15: 26.07609 | AI15: 24.96038 | AJ15: 23.73738 | AL15: 150 | AM15: 6.74247 | AN15: 6.84743 | AO15: 6.71467 | AP15: 6.88218 | AQ15: 6.71502 | AR15: 6.84771 | AS15: 6.78741 | AT15: 6.82305 | AU15: 6.71746 | AV15: 6.83408
N16: 160 | O16: 86.65319 | P16: 86.75905 | Q16: 87.01648 | R16: 86.88548 | S16: 86.95642 | T16: 86.91099 | U16: 86.23912 | V16: 86.77659 | W16: 86.41206 | X16: 86.89504 | Z16: 160 | AA16: 23.17146 | AB16: 23.17992 | AC16: 25.82457 | AD16: 24.55413 | AE16: 22.11415 | AF16: 25.94442 | AG16: 23.23022 | AH16: 25.67477 | AI16: 25.34249 | AJ16: 23.89255 | AL16: 160 | AM16: 6.77556 | AN16: 6.88053 | AO16: 6.74802 | AP16: 6.91533 | AQ16: 6.74827 | AR16: 6.8809 | AS16: 6.81987 | AT16: 6.85625 | AU16: 6.75032 | AV16: 6.86734
N17: 170 | O17: 87.99125 | P17: 88.18898 | Q17: 88.35462 | R17: 88.40807 | S17: 88.29012 | T17: 88.35767 | U17: 87.57703 | V17: 88.12992 | W17: 87.74086 | X17: 88.36569 | Z17: 170 | AA17: 23.25918 | AB17: 23.05118 | AC17: 26.13338 | AD17: 24.47855 | AE17: 22.50312 | AF17: 25.89298 | AG17: 23.63036 | AH17: 25.32267 | AI17: 25.7338 | AJ17: 23.94823 | AL17: 170 | AM17: 6.80417 | AN17: 6.90983 | AO17: 6.77746 | AP17: 6.94489 | AQ17: 6.77635 | AR17: 6.91028 | AS17: 6.84838 | AT17: 6.88484 | AU17: 6.77918 | AV17: 6.89709
N18: 180 | O18: 89.48285 | P18: 89.75625 | Q18: 89.87994 | R18: 90.06488 | S18: 89.79933 | T18: 89.93591 | U18: 89.09529 | V18: 89.60654 | W18: 89.27134 | X18: 89.94258 | Z18: 180 | AA18: 23.19004 | AB18: 22.77594 | AC18: 26.30866 | AD18: 24.29208 | AE18: 22.83547 | AF18: 25.82076 | AG18: 23.97637 | AH18: 24.89923 | AI18: 25.95067 | AJ18: 23.87687 | AL18: 180 | AM18: 6.8291 | AN18: 6.93538 | AO18: 6.80228 | AP18: 6.97154 | AQ18: 6.80142 | AR18: 6.9359 | AS18: 6.87266 | AT18: 6.91028 | AU18: 6.80428 | AV18: 6.92262
L19: Limit | N19: 190 | O19: 90.87043 | P19: 91.2049 | Q19: 91.26992 | R19: 91.52225 | S19: 91.17974 | T19: 91.40258 | U19: 90.47265 | V19: 91.02501 | W19: 90.65656 | X19: 91.39064 | Z19: 190 | AA19: 22.93248 | AB19: 22.26505 | AC19: 26.30032 | AD19: 23.8915 | AE19: 22.97315 | AF19: 25.58564 | AG19: 24.15867 | AH19: 24.33246 | AI19: 25.86683 | AJ19: 23.5562 | AL19: 190 | AM19: 6.85127 | AN19: 6.9587 | AO19: 6.82551 | AP19: 6.99566 | AQ19: 6.82456 | AR19: 6.95857 | AS19: 6.89537 | AT19: 6.93431 | AU19: 6.82691 | AV19: 6.9458
K20: 100 | L20: 50 | N20: 200 | O20: 92.17379 | P20: 92.51305 | Q20: 92.57837 | R20: 92.82501 | S20: 92.48501 | T20: 92.72405 | U20: 91.77812 | V20: 92.32757 | W20: 91.96381 | X20: 92.688 | Z20: 200 | AA20: 22.46475 | AB20: 21.56821 | AC20: 26.1268 | AD20: 23.2756 | AE20: 22.84236 | AF20: 25.16184 | AG20: 24.05504 | AH20: 23.55315 | AI20: 25.61254 | AJ20: 23.0185 | AL20: 200 | AM20: 6.87229 | AN20: 6.97983 | AO20: 6.84733 | AP20: 7.01774 | AQ20: 6.84594 | AR20: 6.97961 | AS20: 6.91674 | AT20: 6.9565 | AU20: 6.84736 | AV20: 6.9685
K21: 212 | L21: 50 | N21: 212 | O21: 93.41461 | P21: 93.73582 | Q21: 93.80664 | R21: 94.02052 | S21: 93.71661 | T21: 93.96539 | U21: 93.00961 | V21: 93.56494 | W21: 93.19038 | X21: 93.89335 | Z21: 212 | AA21: 21.739 | AB21: 20.56903 | AC21: 25.77018 | AD21: 22.29577 | AE21: 22.34605 | AF21: 24.35757 | AG21: 23.56361 | AH21: 22.46073 | AI21: 25.07511 | AJ21: 22.13399 | AL21: 212 | AM21: 6.89564 | AN21: 7.0051 | AO21: 6.87137 | AP21: 7.04193 | AQ21: 6.86826 | AR21: 7.00391 | AS21: 6.94046 | AT21: 6.98077 | AU21: 6.87071 | AV21: 6.9937
K22: 300 | L22: 35 | N22: 224 | O22: 94.58133 | P22: 94.83544 | Q22: 94.96412 | R22: 95.09504 | S22: 94.88463 | T22: 95.09213 | U22: 94.16706 | V22: 94.72399 | W22: 94.3404 | X22: 94.99684 | Z22: 224 | AA22: 20.91531 | AB22: 19.44766 | AC22: 25.30127 | AD22: 21.11352 | AE22: 21.51791 | AF22: 23.25168 | AG22: 22.74506 | AH22: 21.2204 | AI22: 24.32026 | AJ22: 21.07718 | AL22: 224 | AM22: 6.9184 | AN22: 7.02807 | AO22: 6.89338 | AP22: 7.06545 | AQ22: 6.88994 | AR22: 7.02628 | AS22: 6.9621 | AT22: 7.00418 | AU22: 6.8932 | AV22: 7.01712
K23: 400 | L23: 25 | N23: 236 | O23: 95.66371 | P23: 95.83998 | Q23: 96.02331 | R23: 96.07161 | S23: 95.95407 | T23: 96.11569 | U23: 95.22063 | V23: 95.78266 | W23: 95.39333 | X23: 96.01618 | Z23: 236 | AA23: 19.91487 | AB23: 18.17643 | AC23: 24.68151 | AD23: 19.72117 | AE23: 20.35326 | AF23: 21.84748 | AG23: 21.55642 | AH23: 19.81425 | AI23: 23.33959 | AJ23: 19.79483 | AL23: 236 | AM23: 6.93998 | AN23: 7.05033 | AO23: 6.9142 | AP23: 7.08806 | AQ23: 6.91053 | AR23: 7.04906 | AS23: 6.98314 | AT23: 7.02597 | AU23: 6.91565 | AV23: 7.04024
K24: 500 | L24: 20 | N24: 250 | O24: 96.76289 | P24: 96.86008 | Q24: 97.11156 | R24: 97.09403 | S24: 97.0517 | T24: 97.1486 | U24: 96.30736 | V24: 96.82673 | W24: 96.48025 | X24: 97.05929 | Z24: 250 | AA24: 18.7221 | AB24: 16.71544 | AC24: 23.92589 | AD24: 18.08973 | AE24: 18.88042 | AF24: 20.182 | AG24: 20.03222 | AH24: 18.26767 | AI24: 22.0949 | AJ24: 18.23914 | AL24: 250 | AM24: 6.96521 | AN24: 7.07697 | AO24: 6.93814 | AP24: 7.11458 | AQ24: 6.93281 | AR24: 7.07487 | AS24: 7.00701 | AT24: 7.05136 | AU24: 6.9407 | AV24: 7.06659
K25: 600 | L25: 15 | N25: 265 | O25: 97.97399 | P25: 98.02739 | Q25: 98.31012 | R25: 98.26789 | S25: 98.25602 | T25: 98.33551 | U25: 97.50298 | V25: 98.00569 | W25: 97.67446 | X25: 98.25879 | Z25: 265 | AA25: 17.69038 | AB25: 15.35916 | AC25: 23.34624 | AD25: 16.51868 | AE25: 17.47685 | AF25: 18.61963 | AG25: 18.58461 | AH25: 16.89781 | AI25: 20.94896 | AJ25: 16.75676 | AL25: 265 | AM25: 6.99212 | AN25: 7.10651 | AO25: 6.96573 | AP25: 7.14194 | AQ25: 6.95692 | AR25: 7.10245 | AS25: 7.03176 | AT25: 7.07891 | AU25: 6.9679 | AV25: 7.09392
K26: 710 | L26: 12 | N26: 280 | O26: 99.18491 | P26: 99.2093 | Q26: 99.5183 | R26: 99.45968 | S26: 99.46387 | T26: 99.53291 | U26: 98.70331 | V26: 99.19381 | W26: 98.87687 | X26: 99.46962 | Z26: 280 | AA26: 16.61365 | AB26: 14.0758 | AC26: 22.60614 | AD26: 15.03413 | AE26: 15.9536 | AF26: 17.07667 | AG26: 17.03009 | AH26: 15.53421 | AI26: 19.71503 | AJ26: 15.34812 | AL26: 280 | AM26: 7.01933 | AN26: 7.13693 | AO26: 6.99291 | AP26: 7.17152 | AQ26: 6.98154 | AR26: 7.13076 | AS26: 7.05744 | AT26: 7.1065 | AU26: 6.9952 | AV26: 7.12275
K27: 800 | L27: 10 | N27: 300 | O27: 100.46286 | P27: 100.4804 | Q27: 100.79452 | R27: 100.73447 | S27: 100.73775 | T27: 100.81697 | U27: 99.96724 | V27: 100.46317 | W27: 100.14538 | X27: 100.76747 | Z27: 300 | AA27: 15.33006 | AB27: 12.56943 | AC27: 21.56328 | AD27: 13.19992 | AE27: 13.95735 | AF27: 15.08615 | AG27: 15.0151 | AH27: 13.84458 | AI27: 18.14264 | AJ27: 13.62394 | AL27: 300 | AM27: 7.05835 | AN27: 7.17833 | AO27: 7.03062 | AP27: 7.21114 | AQ27: 7.01464 | AR27: 7.16834 | AS27: 7.09364 | AT27: 7.14698 | AU27: 7.03367 | AV27: 7.16306
K28: 900 | L28: 9 | N28: 315 | O28: 101.76527 | P28: 101.76954 | Q28: 102.08859 | R28: 102.02891 | S28: 102.03251 | T28: 102.12565 | U28: 101.2533 | V28: 101.76235 | W28: 101.42952 | X28: 102.08394 | Z28: 315 | AA28: 14.50431 | AB28: 11.67481 | AC28: 20.78223 | AD28: 12.04174 | AE28: 12.58623 | AF28: 13.72231 | AG28: 13.62357 | AH28: 12.73716 | AI28: 17.07783 | AJ28: 12.5527 | AL28: 315 | AM28: 7.08884 | AN28: 7.21108 | AO28: 7.0613 | AP28: 7.2433 | AQ28: 7.04138 | AR28: 7.19928 | AS28: 7.12207 | AT28: 7.1789 | AU28: 7.06469 | AV28: 7.19574
K29: 1000 | L29: 8 | N29: 335 | O29: 103.06684 | P29: 103.04941 | Q29: 103.38324 | R29: 103.31866 | S29: 103.32355 | T29: 103.42692 | U29: 102.54405 | V29: 103.0574 | W29: 102.71683 | X29: 103.39371 | Z29: 335 | AA29: 13.54505 | AB29: 10.71497 | AC29: 19.70929 | AD29: 10.76242 | AE29: 11.07231 | AF29: 12.11539 | AG29: 12.04635 | AH29: 11.52153 | AI29: 15.81509 | AJ29: 11.38986 | AL29: 335 | AM29: 7.13516 | AN29: 7.26065 | AO29: 7.10668 | AP29: 7.29062 | AQ29: 7.0802 | AR29: 7.24514 | AS29: 7.1636 | AT29: 7.22583 | AU29: 7.1105 | AV29: 7.24394
K30: 2000 | L30: 5 | N30: 355 | O30: 104.39252 | P30: 104.3305 | Q30: 104.69934 | R30: 104.61496 | S30: 104.63625 | T30: 104.73062 | U30: 103.86252 | V30: 104.36217 | W30: 104.02754 | X30: 104.70931 | Z30: 355 | AA30: 12.6251 | AB30: 9.93375 | AC30: 18.54751 | AD30: 9.77123 | AE30: 9.88883 | AF30: 10.82318 | AG30: 10.79225 | AH30: 10.57914 | AI30: 14.65155 | AJ30: 10.45147 | AL30: 355 | AM30: 7.18752 | AN30: 7.31653 | AO30: 7.15866 | AP30: 7.34496 | AQ30: 7.12311 | AR30: 7.29598 | AS30: 7.21054 | AT30: 7.2788 | AU30: 7.16231 | AV30: 7.29767
K31: 4500 | L31: 5 | N31: 375 | O31: 105.76305 | P31: 105.64271 | Q31: 106.05544 | R31: 105.94569 | S31: 105.99447 | T31: 106.05863 | U31: 105.23268 | V31: 105.69973 | W31: 105.38532 | X31: 106.05605 | Z31: 375 | AA31: 11.72438 | AB31: 9.26269 | AC31: 17.32236 | AD31: 8.99953 | AE31: 8.98606 | AF31: 9.83018 | AG31: 9.82021 | AH31: 9.85582 | AI31: 13.56283 | AJ31: 9.70634 | AL31: 375 | AM31: 7.24752 | AN31: 7.38022 | AO31: 7.21651 | AP31: 7.40566 | AQ31: 7.17174 | AR31: 7.3535 | AS31: 7.26263 | AT31: 7.33668 | AU31: 7.22268 | AV31: 7.3592
... K35: 14000 | L35: 5 | N35: 475 | O35: 110.72017 | P35: 110.61532 | Q35: 111.06165 | R35: 110.97443 | S35: 111.07218 | T35: 110.80305 | U35: 110.4831 | V35: 110.72638 | W35: 110.50816 | X35: 110.81317 | Z35: 475 | AA35: 8.75964 | AB35: 7.44257 | AC35: 12.22619 | AD35: 7.07393 | AE35: 7.08609 | AF35: 7.59886 | AG35: 7.77175 | AH35: 8.30565 | AI35: 9.85735 | AJ35: 8.03339 | AL35: 475 | AM35: 7.69897 | AN35: 7.84639 | AO35: 7.66683 | AP35: 7.86878 | AQ35: 7.55393 | AR35: 7.79478 | AS35: 7.66466 | AT35: 7.76534 | AU35: 7.67706 | AV35: 7.82465
N36: 500 | O36: 111.79665 | P36: 111.74513 | Q36: 112.20198 | R36: 112.11618 | S36: 112.22539 | T36: 111.80206 | U36: 111.71178 | V36: 111.86932 | W36: 111.68227 | X36: 111.8264 | Z36: 500 | AA36: 8.17212 | AB36: 7.05899 | AC36: 11.1799 | AD36: 6.72267 | AE36: 6.73336 | AF36: 7.17686 | AG36: 7.38476 | AH36: 7.93456 | AI36: 9.12711 | AJ36: 7.68341 | AL36: 500 | AM36: 7.84844 | AN36: 7.99402 | AO36: 7.81554 | AP36: 8.01931 | AQ36: 7.69021 | AR36: 7.93906 | AS36: 7.80321 | AT36: 7.90447 | AU36: 7.82365 | AV36: 7.97672
N37: 530 | O37: 112.89561 | P37: 112.84942 | Q37: 113.32756 | R37: 113.23697 | S37: 113.35386 | T37: 112.82193 | U37: 112.94456 | V37: 112.99214 | W37: 112.85542 | X37: 112.86443 | Z37: 530 | AA37: 7.54882 | AB37: 6.59236 | AC37: 10.07002 | AD37: 6.31213 | AE37: 6.33188 | AF37: 6.70343 | AG37: 6.92983 | AH37: 7.46665 | AI37: 8.3346 | AJ37: 7.25048 | AL37: 530 | AM37: 8.03726 | AN37: 8.17306 | AO37: 7.99869 | AP37: 8.2045 | AQ37: 7.87277 | AR37: 8.11584 | AS37: 7.98021 | AT37: 8.07321 | AU37: 8.00795 | AV37: 8.16259
N38: 560 | O38: 113.91866 | P38: 113.84614 | Q38: 114.33935 | R38: 114.24935 | S38: 114.36927 | T38: 113.77464 | U38: 114.06636 | V38: 113.99843 | W38: 113.92926 | X38: 113.83624 | Z38: 560 | AA38: 7.03406 | AB38: 6.20755 | AC38: 9.15802 | AD38: 5.99147 | AE38: 5.97357 | AF38: 6.33268 | AG38: 6.55253 | AH38: 7.02115 | AI38: 7.69076 | AJ38: 6.87896 | AL38: 560 | AM38: 8.21715 | AN38: 8.33717 | AO38: 8.17296 | AP38: 8.37773 | AQ38: 8.05497 | AR38: 8.28681 | AS38: 8.1517 | AT38: 8.22883 | AU38: 8.18207 | AV38: 8.33087
N39: 600 | O39: 114.90209 | P39: 114.78277 | Q39: 115.26473 | R39: 115.19552 | S39: 115.29725 | T39: 114.70507 | U39: 115.11425 | V39: 114.92335 | W39: 114.93918 | X39: 114.78097 | Z39: 600 | AA39: 6.57625 | AB39: 5.82894 | AC39: 8.229 | AD39: 5.65328 | AE39: 5.60273 | AF39: 5.97237 | AG39: 6.16851 | AH39: 6.5129 | AI39: 7.05662 | AJ39: 6.49122 | AL39: 600 | AM39: 8.38562 | AN39: 8.49133 | AO39: 8.33602 | AP39: 8.54849 | AQ39: 8.27029 | AR39: 8.46949 | AS39: 8.34567 | AT39: 8.38834 | AU39: 8.34594 | AV39: 8.50454
N40: 630 | O40: 115.78892 | P40: 115.61368 | Q40: 116.05649 | R40: 116.02609 | S40: 116.08629 | T40: 115.57103 | U40: 116.02739 | V40: 115.71823 | W40: 115.82569 | X40: 115.64587 | Z40: 630 | AA40: 6.30836 | AB40: 5.58228 | AC40: 7.67244 | AD40: 5.44761 | AE40: 5.3762 | AF40: 5.75042 | AG40: 5.92854 | AH40: 6.14843 | AI40: 6.69408 | AJ40: 6.22678 | AL40: 630 | AM40: 8.44871 | AN40: 8.55382 | AO40: 8.40143 | AP40: 8.61818 | AQ40: 8.389 | AR40: 8.55474 | AS40: 8.44978 | AT40: 8.46832 | AU40: 8.41181 | AV40: 8.58629
N41: 670 | O41: 116.55036 | P41: 116.3583 | Q41: 116.70817 | R41: 116.7638 | S41: 116.74173 | T41: 116.36035 | U41: 116.79651 | V41: 116.40065 | W41: 116.58395 | X41: 116.41396 | Z41: 670 | AA41: 5.94163 | AB41: 5.27618 | AC41: 6.99064 | AD41: 5.17566 | AE41: 5.05129 | AF41: 5.44429 | AG41: 5.58909 | AH41: 5.61476 | AI41: 6.23454 | AJ41: 5.82944 | AL41: 670 | AM41: 8.42162 | AN41: 8.53857 | AO41: 8.38008 | AP41: 8.61074 | AQ41: 8.44097 | AR41: 8.56886 | AS41: 8.49369 | AT41: 8.49866 | AU41: 8.39117 | AV41: 8.60397
N42: 710 | O42: 117.12608 | P42: 116.95843 | Q42: 117.18606 | R42: 117.34427 | S42: 117.22684 | T42: 116.98389 | U42: 117.37336 | V42: 116.93506 | W42: 117.16582 | X42: 117.01275 | Z42: 710 | AA42: 5.53503 | AB42: 4.9402 | AC42: 6.34325 | AD42: 4.89913 | AE42: 4.69628 | AF42: 5.12053 | AG42: 5.221 | AH42: 5.07717 | AI42: 5.77503 | AJ42: 5.40587 | AL42: 710 | AM42: 8.3062 | AN42: 8.44341 | AO42: 8.26778 | AP42: 8.51479 | AQ42: 8.37718 | AR42: 8.4871 | AS42: 8.43176 | AT42: 8.44283 | AU42: 8.27785 | AV42: 8.52138
N43: 750 | O43: 117.51657 | P43: 117.3935 | Q43: 117.49957 | R43: 117.75039 | S43: 117.54523 | T43: 117.42445 | U43: 117.76404 | V43: 117.31528 | W43: 117.57087 | X43: 117.43062 | Z43: 750 | AA43: 5.12651 | AB43: 4.61894 | AC43: 5.74523 | AD43: 4.62441 | AE43: 4.34861 | AF43: 4.80423 | AG43: 4.85893 | AH43: 4.59057 | AI43: 5.34957 | AJ43: 5.00122 | AL43: 750 | AM43: 8.13428 | AN43: 8.28625 | AO43: 8.10253 | AP43: 8.35681 | AQ43: 8.22948 | AR43: 8.34183 | AS43: 8.2939 | AT43: 8.30963 | AU43: 8.11227 | AV43: 8.36215
...

Sheet Shock temp
N1: SPL RAW DATA | Z1: THD RAW DATA | AL1: IMPEDANCE RAW DATA
N2: SPL specification / | S2: SPK :117.4 dB±2dB Average of frequency 0.8, 1.0, 1.2k, 1.5k, 3.58V | Z2: THD Limit / | AE2: 100-212Hz 50%300Hz 35%, 400Hz 25%, 500Hz 20%,600Hz 15%, 710Hz 12%, 800Hz 10%, 900Hz 9%,1KHz 8%, 2K~4.5KHz 5%, 5KHz 8%, 6KHz 8%,7.1-14KHz 5% with 3.58V | AL2: Imp / F0 Limit / | AQ2: IMP:8 Ω ±15% at 2kHz, 3.58V , F0: 615 ± 120Hz at 3.58V
N3: Evalution standard / | S3: Deviation before test and after test is under ± 2db, and SPL Average value in limit / | Z3: Evalution standard / | AE3: THD value in limit / | AL3: Evalution standard / | AQ3: Value in limit /
N4: Test condition / | S4: Low temperature(-40℃ ± 5℃) 30 minutes → Hight temperature (+85℃ ± 5℃) 30 minutes/1Cycle, 96 cycle | Z4: Test condition / | AE4: Low temperature(-40℃ ± 5℃) 30 minutes → Hight temperature (+85℃ ± 5℃) 30 minutes/1Cycle, 96 cycle | AL4: Test condition / | AQ4: Low temperature(-40℃ ± 5℃) 30 minutes → Hight temperature (+85℃ ± 5℃) 30 minutes/1Cycle, 96 cycle
N5: Sample No | O5: #1 | Q5: #2 | S5: #3 | U5: #4 | W5: #5 | Z5: Sample No | AA5: #1 | AC5: #2 | AE5: #3 | AG5: #4 | AI5: #5 | AL5: Sample No | AM5: #1 | AO5: #2 | AQ5: #3 | AS5: #4 | AU5: #5
N6: Result | O6: OK | P6: OK | Q6: OK | R6: OK | S6: OK | T6: OK | U6: OK | V6: OK | W6: OK | X6: OK | AM6: OK | AN6: OK | AO6: OK | AP6: OK | AQ6: OK | AR6: OK | AS6: OK | AT6: OK | AU6: OK | AV6: OK
O7: Before #1 | P7: After #1 | Q7: Before #2 | R7: After #2 | S7: Before #3 | T7: After #3 | U7: Before #4 | V7: After #4 | W7: Before #5 | X7: After #5 | AA7: Before #1 | AB7: After #1 | AC7: Before #2 | AD7: After #2 | AE7: Before #3 | AF7: After #3 | AG7: Before #4 | AH7: After #4 | AI7: Before #5 | AJ7: After #5 | AM7: Before #1 | AN7: After #1 | AO7: Before #2 | AP7: After #2 | AQ7: Before #3 | AR7: After #3 | AS7: Before #4 | AT7: After #4 | AU7: Before #5 | AV7: After #5
N8: 100 | O8: 79.38461 | P8: 78.90097 | Q8: 78.90195 | R8: 78.13649 | S8: 78.7663 | T8: 78.20513 | U8: 79.17445 | V8: 78.04309 | W8: 78.50036 | X8: 77.7564 | Z8: 100 | AA8: 22.62202 | AB8: 23.53933 | AC8: 21.95594 | AD8: 26.0735 | AE8: 20.53055 | AF8: 22.93365 | AG8: 20.68614 | AH8: 22.07168 | AI8: 23.15838 | AJ8: 23.10981 | AL8: 100 | AM8: 6.40026 | AN8: 6.62123 | AO8: 6.46605 | AP8: 6.64342 | AQ8: 6.43037 | AR8: 6.63289 | AS8: 6.45835 | AT8: 6.70758 | AU8: 6.44376 | AV8: 6.75115
N9: 106 | O9: 79.78727 | P9: 79.35557 | Q9: 79.29989 | R9: 78.59489 | S9: 79.17372 | T9: 78.63463 | U9: 79.57705 | V9: 78.50329 | W9: 78.93171 | X9: 78.25543 | Z9: 106 | AA9: 22.82765 | AB9: 23.72314 | AC9: 22.17945 | AD9: 25.89454 | AE9: 20.68592 | AF9: 23.09286 | AG9: 20.84892 | AH9: 22.14269 | AI9: 23.35498 | AJ9: 23.18399 | AL9: 106 | AM9: 6.4688 | AN9: 6.68508 | AO9: 6.53445 | AP9: 6.70827 | AQ9: 6.4978 | AR9: 6.69719 | AS9: 6.52438 | AT9: 6.77046 | AU9: 6.51041 | AV9: 6.80804
N10: 112 | O10: 80.30258 | P10: 79.87033 | Q10: 79.78952 | R10: 79.07295 | S10: 79.66976 | T10: 79.184 | U10: 80.07237 | V10: 79.04921 | W10: 79.43919 | X10: 78.79599 | Z10: 112 | AA10: 23.02163 | AB10: 23.89372 | AC10: 22.3992 | AD10: 25.82596 | AE10: 20.84151 | AF10: 23.30241 | AG10: 20.98758 | AH10: 22.2401 | AI10: 23.56881 | AJ10: 23.27424 | AL10: 112 | AM10: 6.52188 | AN10: 6.73347 | AO10: 6.58717 | AP10: 6.75724 | AQ10: 6.55352 | AR10: 6.74813 | AS10: 6.57535 | AT10: 6.81914 | AU10: 6.56432 | AV10: 6.85501
N11: 118 | O11: 81.21825 | P11: 80.80155 | Q11: 80.69715 | R11: 80.0382 | S11: 80.58394 | T11: 80.12738 | U11: 80.9892 | V11: 80.06658 | W11: 80.35493 | X11: 79.75144 | Z11: 118 | AA11: 23.25645 | AB11: 24.12066 | AC11: 22.67427 | AD11: 25.843 | AE11: 21.05224 | AF11: 23.5651 | AG11: 21.15466 | AH11: 22.39264 | AI11: 23.86298 | AJ11: 23.41992 | AL11: 118 | AM11: 6.56621 | AN11: 6.77493 | AO11: 6.63046 | AP11: 6.79712 | AQ11: 6.59845 | AR11: 6.79189 | AS11: 6.61809 | AT11: 6.86047 | AU11: 6.60922 | AV11: 6.89455
N12: 125 | O12: 82.19396 | P12: 81.86773 | Q12: 81.71871 | R12: 81.14505 | S12: 81.60903 | T12: 81.19481 | U12: 82.03476 | V12: 81.17454 | W12: 81.39677 | X12: 80.84196 | Z12: 125 | AA12: 23.55627 | AB12: 24.467 | AC12: 23.01979 | AD12: 25.95412 | AE12: 21.33051 | AF12: 23.89388 | AG12: 21.41062 | AH12: 22.60186 | AI12: 24.2643 | AJ12: 23.63765 | AL12: 125 | AM12: 6.60838 | AN12: 6.81598 | AO12: 6.67408 | AP12: 6.83776 | AQ12: 6.64032 | AR12: 6.8317 | AS12: 6.6603 | AT12: 6.90125 | AU12: 6.65172 | AV12: 6.93325
N13: 132 | O13: 83.33845 | P13: 83.0319 | Q13: 82.85295 | R13: 82.35869 | S13: 82.74257 | T13: 82.36019 | U13: 83.18476 | V13: 82.3806 | W13: 82.54186 | X13: 82.05321 | Z13: 132 | AA13: 24.18348 | AB13: 25.05336 | AC13: 23.72124 | AD13: 25.71026 | AE13: 21.89114 | AF13: 24.54489 | AG13: 21.93118 | AH13: 23.03954 | AI13: 25.02456 | AJ13: 24.10537 | AL13: 132 | AM13: 6.64386 | AN13: 6.85184 | AO13: 6.71074 | AP13: 6.8723 | AQ13: 6.67626 | AR13: 6.86444 | AS13: 6.69584 | AT13: 6.93492 | AU13: 6.68828 | AV13: 6.96703
N14: 140 | O14: 84.56778 | P14: 84.21244 | Q14: 84.07048 | R14: 83.63011 | S14: 83.94976 | T14: 83.61737 | U14: 84.39562 | V14: 83.67108 | W14: 83.72631 | X14: 83.29015 | Z14: 140 | AA14: 24.97481 | AB14: 25.60973 | AC14: 24.5984 | AD14: 26.10581 | AE14: 22.50126 | AF14: 25.26978 | AG14: 22.60064 | AH14: 23.54638 | AI14: 25.86477 | AJ14: 24.53548 | AL14: 140 | AM14: 6.67789 | AN14: 6.88746 | AO14: 6.7477 | AP14: 6.9064 | AQ14: 6.7113 | AR14: 6.89809 | AS14: 6.7312 | AT14: 6.96814 | AU14: 6.72508 | AV14: 7.00048
N15: 150 | O15: 85.79135 | P15: 85.48557 | Q15: 85.27734 | R15: 84.98225 | S15: 85.16563 | T15: 84.89735 | U15: 85.61386 | V15: 84.99411 | W15: 84.92471 | X15: 84.60254 | Z15: 150 | AA15: 25.73613 | AB15: 25.9626 | AC15: 25.45486 | AD15: 26.63939 | AE15: 23.24814 | AF15: 25.9782 | AG15: 23.25725 | AH15: 24.07194 | AI15: 26.53032 | AJ15: 24.84239 | AL15: 150 | AM15: 6.71645 | AN15: 6.92435 | AO15: 6.78576 | AP15: 6.94331 | AQ15: 6.74923 | AR15: 6.93496 | AS15: 6.77052 | AT15: 7.00456 | AU15: 6.76442 | AV15: 7.03496
N16: 160 | O16: 87.02117 | P16: 86.82956 | Q16: 86.4956 | R16: 86.33024 | S16: 86.38525 | T16: 86.21157 | U16: 86.8462 | V16: 86.3252 | W16: 86.14553 | X16: 85.99805 | Z16: 160 | AA16: 25.99258 | AB16: 26.06666 | AC16: 25.80625 | AD16: 26.88559 | AE16: 23.57635 | AF16: 26.32026 | AG16: 23.52018 | AH16: 24.37206 | AI16: 26.72268 | AJ16: 24.94636 | AL16: 160 | AM16: 6.74848 | AN16: 6.95617 | AO16: 6.8181 | AP16: 6.97366 | AQ16: 6.78215 | AR16: 6.96558 | AS16: 6.80343 | AT16: 7.03611 | AU16: 6.79743 | AV16: 7.06424
N17: 170 | O17: 88.37841 | P17: 88.31089 | Q17: 87.84144 | R17: 87.72526 | S17: 87.72667 | T17: 87.59331 | U17: 88.21016 | V17: 87.69446 | W17: 87.50257 | X17: 87.48753 | Z17: 170 | AA17: 26.28196 | AB17: 26.16184 | AC17: 26.14828 | AD17: 27.03102 | AE17: 23.96769 | AF17: 26.63495 | AG17: 23.8501 | AH17: 24.65333 | AI17: 26.9487 | AJ17: 25.07471 | AL17: 170 | AM17: 6.7765 | AN17: 6.98551 | AO17: 6.84597 | AP17: 7.00121 | AQ17: 6.81002 | AR17: 6.99272 | AS17: 6.83125 | AT17: 7.06302 | AU17: 6.8262 | AV17: 7.08943
N18: 180 | O18: 89.86556 | P18: 89.87634 | Q18: 89.371 | R18: 89.16746 | S18: 89.2485 | T18: 89.06325 | U18: 89.77055 | V18: 89.11468 | W18: 89.04776 | X18: 89.05409 | Z18: 180 | AA18: 26.47902 | AB18: 26.10959 | AC18: 26.34485 | AD18: 27.17497 | AE18: 24.24185 | AF18: 26.79278 | AG18: 24.09876 | AH18: 24.88442 | AI18: 27.04891 | AJ18: 25.16151 | AL18: 180 | AM18: 6.80136 | AN18: 7.01154 | AO18: 6.87086 | AP18: 7.02411 | AQ18: 6.83454 | AR18: 7.01653 | AS18: 6.85537 | AT18: 7.08747 | AU18: 6.85069 | AV18: 7.11161
L19: Limit | N19: 190 | O19: 91.23655 | P19: 91.30186 | Q19: 90.76958 | R19: 90.53808 | S19: 90.63243 | T19: 90.44212 | U19: 91.17047 | V19: 90.4615 | W19: 90.45495 | X19: 90.4616 | Z19: 190 | AA19: 26.46458 | AB19: 25.83304 | AC19: 26.33177 | AD19: 27.10449 | AE19: 24.34785 | AF19: 26.69983 | AG19: 24.18677 | AH19: 24.91742 | AI19: 26.91624 | AJ19: 25.06416 | AL19: 190 | AM19: 6.82341 | AN19: 7.03255 | AO19: 6.89387 | AP19: 7.04602 | AQ19: 6.85696 | AR19: 7.03861 | AS19: 6.878 | AT19: 7.1082 | AU19: 6.87356 | AV19: 7.13257
K20: 100 | L20: 50 | N20: 200 | O20: 92.53152 | P20: 92.60036 | Q20: 92.07295 | R20: 91.81382 | S20: 91.94124 | T20: 91.72909 | U20: 92.49055 | V20: 91.71502 | W20: 91.77237 | X20: 91.73308 | Z20: 200 | AA20: 26.16449 | AB20: 25.31539 | AC20: 26.04409 | AD20: 26.76535 | AE20: 24.20242 | AF20: 26.32716 | AG20: 24.03517 | AH20: 24.7041 | AI20: 26.50642 | AJ20: 24.71298 | AL20: 200 | AM20: 6.84462 | AN20: 7.05311 | AO20: 6.91477 | AP20: 7.06569 | AQ20: 6.87775 | AR20: 7.0595 | AS20: 6.89889 | AT20: 7.1283 | AU20: 6.8952 | AV20: 7.15191
K21: 212 | L21: 50 | N21: 212 | O21: 93.76254 | P21: 93.79708 | Q21: 93.3019 | R21: 93.00541 | S21: 93.17439 | T21: 92.94486 | U21: 93.72584 | V21: 92.90453 | W21: 93.00358 | X21: 92.90776 | Z21: 212 | AA21: 25.41651 | AB21: 24.40977 | AC21: 25.3262 | AD21: 25.94765 | AE21: 23.68901 | AF21: 25.49776 | AG21: 23.44486 | AH21: 24.11071 | AI21: 25.65113 | AJ21: 23.9166 | AL21: 212 | AM21: 6.86766 | AN21: 7.07649 | AO21: 6.93743 | AP21: 7.08795 | AQ21: 6.90076 | AR21: 7.08243 | AS21: 6.92192 | AT21: 7.1504 | AU21: 6.91873 | AV21: 7.17329
K22: 300 | L22: 35 | N22: 224 | O22: 94.94116 | P22: 94.90421 | Q22: 94.46236 | R22: 94.14796 | S22: 94.33302 | T22: 94.09404 | U22: 94.88117 | V22: 94.04746 | W22: 94.14875 | X22: 93.99688 | Z22: 224 | AA22: 24.30164 | AB22: 23.35352 | AC22: 24.25171 | AD22: 24.79968 | AE22: 22.90982 | AF22: 24.34653 | AG22: 22.52494 | AH22: 23.26771 | AI22: 24.56282 | AJ22: 22.79989 | AL22: 224 | AM22: 6.88979 | AN22: 7.09833 | AO22: 6.95983 | AP22: 7.10896 | AQ22: 6.92291 | AR22: 7.10407 | AS22: 6.9437 | AT22: 7.17138 | AU22: 6.9422 | AV22: 7.19333
K23: 400 | L23: 25 | N23: 236 | O23: 96.02288 | P23: 95.93423 | Q23: 95.51181 | R23: 95.23594 | S23: 95.39425 | T23: 95.17944 | U23: 95.9393 | V23: 95.14115 | W23: 95.19158 | X23: 95.02308 | Z23: 236 | AA23: 22.81554 | AB23: 22.17267 | AC23: 22.79882 | AD23: 23.34962 | AE23: 21.86876 | AF23: 22.86716 | AG23: 21.23787 | AH23: 22.17682 | AI23: 23.22174 | AJ23: 21.47104 | AL23: 236 | AM23: 6.91002 | AN23: 7.11987 | AO23: 6.98009 | AP23: 7.12847 | AQ23: 6.94316 | AR23: 7.12348 | AS23: 6.96568 | AT23: 7.19224 | AU23: 6.96424 | AV23: 7.21205
K24: 500 | L24: 20 | N24: 250 | O24: 97.12716 | P24: 96.99664 | Q24: 96.59236 | R24: 96.31674 | S24: 96.48903 | T24: 96.2674 | U24: 97.04152 | V24: 96.22691 | W24: 96.27285 | X24: 96.07597 | Z24: 250 | AA24: 21.00021 | AB24: 20.84146 | AC24: 21.04141 | AD24: 21.51424 | AE24: 20.58817 | AF24: 21.03568 | AG24: 19.63371 | AH24: 20.80545 | AI24: 21.71005 | AJ24: 19.85168 | AL24: 250 | AM24: 6.93257 | AN24: 7.14339 | AO24: 7.00311 | AP24: 7.15037 | AQ24: 6.96659 | AR24: 7.14669 | AS24: 6.99046 | AT24: 7.21476 | AU24: 6.98968 | AV24: 7.23471
K25: 600 | L25: 15 | N25: 265 | O25: 98.34032 | P25: 98.19446 | Q25: 97.79337 | R25: 97.51599 | S25: 97.69202 | T25: 97.47825 | U25: 98.25245 | V25: 97.43071 | W25: 97.4652 | X25: 97.27004 | Z25: 265 | AA25: 19.35737 | AB25: 19.59055 | AC25: 19.44625 | AD25: 19.65183 | AE25: 19.40918 | AF25: 19.26443 | AG25: 18.12401 | AH25: 19.44491 | AI25: 20.40543 | AJ25: 18.26265 | AL25: 265 | AM25: 6.95699 | AN25: 7.16888 | AO25: 7.02814 | AP25: 7.17583 | AQ25: 6.99097 | AR25: 7.17059 | AS25: 7.0163 | AT25: 7.23924 | AU25: 7.01622 | AV25: 7.25975
K26: 710 | L26: 12 | N26: 280 | O26: 99.55391 | P26: 99.40575 | Q26: 98.99571 | R26: 98.72662 | S26: 98.90047 | T26: 98.69742 | U26: 99.46708 | V26: 98.64011 | W26: 98.66633 | X26: 98.47349 | Z26: 280 | AA26: 17.69057 | AB26: 18.26343 | AC26: 17.84233 | AD26: 17.8043 | AE26: 18.17735 | AF26: 17.53207 | AG26: 16.53361 | AH26: 18.069 | AI26: 19.02414 | AJ26: 16.61051 | AL26: 280 | AM26: 6.98237 | AN26: 7.19566 | AO26: 7.05346 | AP26: 7.19973 | AQ26: 7.01596 | AR26: 7.19484 | AS26: 7.04413 | AT26: 7.26439 | AU26: 7.0441 | AV26: 7.28355
K27: 800 | L27: 10 | N27: 300 | O27: 100.82998 | P27: 100.68642 | Q27: 100.25959 | R27: 100.00435 | S27: 100.17495 | T27: 99.99056 | U27: 100.74773 | V27: 99.92028 | W27: 99.93211 | X27: 99.75078 | Z27: 300 | AA27: 15.56417 | AB27: 16.62207 | AC27: 15.85686 | AD27: 15.49955 | AE27: 16.57542 | AF27: 15.37757 | AG27: 14.50848 | AH27: 16.27009 | AI27: 17.32987 | AJ27: 14.4965 | AL27: 300 | AM27: 7.01824 | AN27: 7.23587 | AO27: 7.08925 | AP27: 7.23518 | AQ27: 7.04985 | AR27: 7.22943 | AS27: 7.08402 | AT27: 7.29849 | AU27: 7.083 | AV27: 7.3173
K28: 900 | L28: 9 | N28: 315 | O28: 102.12975 | P28: 101.99304 | Q28: 101.54575 | R28: 101.30404 | S28: 101.46596 | T28: 101.30284 | U28: 102.04153 | V28: 101.22165 | W28: 101.21348 | X28: 101.04783 | Z28: 315 | AA28: 14.14038 | AB28: 15.53911 | AC28: 14.50237 | AD28: 13.95028 | AE28: 15.43662 | AF28: 13.9344 | AG28: 13.11762 | AH28: 15.02323 | AI28: 16.195 | AJ28: 13.04462 | AL28: 315 | AM28: 7.04631 | AN28: 7.26654 | AO28: 7.11802 | AP28: 7.26358 | AQ28: 7.07773 | AR28: 7.25733 | AS28: 7.11571 | AT28: 7.32602 | AU28: 7.11575 | AV28: 7.34419
K29: 1000 | L29: 8 | N29: 335 | O29: 103.42672 | P29: 103.29762 | Q29: 102.83056 | R29: 102.60277 | S29: 102.76009 | T29: 102.61393 | U29: 103.3371 | V29: 102.5243 | W29: 102.50021 | X29: 102.34958 | Z29: 335 | AA29: 12.54209 | AB29: 14.2713 | AC29: 12.9284 | AD29: 12.21546 | AE29: 14.09479 | AF29: 12.27307 | AG29: 11.51693 | AH29: 13.56166 | AI29: 14.86584 | AJ29: 11.39119 | AL29: 335 | AM29: 7.08746 | AN29: 7.31313 | AO29: 7.15822 | AP29: 7.3034 | AQ29: 7.11747 | AR29: 7.29839 | AS29: 7.16305 | AT29: 7.3661 | AU29: 7.16265 | AV29: 7.38391
K30: 2000 | L30: 5 | N30: 355 | O30: 104.7433 | P30: 104.61331 | Q30: 104.13809 | R30: 103.9172 | S30: 104.0756 | T30: 103.94241 | U30: 104.64791 | V30: 103.84503 | W30: 103.81171 | X30: 103.66746 | Z30: 355 | AA30: 11.28662 | AB30: 13.1283 | AC30: 11.66403 | AD30: 10.86684 | AE30: 12.94341 | AF30: 10.96706 | AG30: 10.25595 | AH30: 12.35997 | AI30: 13.77339 | AJ30: 10.08335 | AL30: 355 | AM30: 7.13479 | AN30: 7.36603 | AO30: 7.2052 | AP30: 7.34954 | AQ30: 7.16186 | AR30: 7.34387 | AS30: 7.21614 | AT30: 7.41141 | AU30: 7.21712 | AV30: 7.42944
K31: 4500 | L31: 5 | N31: 375 | O31: 106.09931 | P31: 105.96362 | Q31: 105.49184 | R31: 105.27636 | S31: 105.4364 | T31: 105.31286 | U31: 105.99146 | V31: 105.21184 | W31: 105.17031 | X31: 105.02733 | Z31: 375 | AA31: 10.33393 | AB31: 12.13605 | AC31: 10.68682 | AD31: 9.85339 | AE31: 11.97643 | AF31: 9.96407 | AG31: 9.29012 | AH31: 11.36718 | AI31: 12.86696 | AJ31: 9.07981 | AL31: 375 | AM31: 7.18902 | AN31: 7.4263 | AO31: 7.25712 | AP31: 7.40164 | AQ31: 7.212 | AR31: 7.39735 | AS31: 7.27848 | AT31: 7.46379 | AU31: 7.27851 | AV31: 7.47887
