Workbook

Sheet BRS 161016S08ZZ
B2: RELIABILITY TEST RESULT | N2: Name | O2: Maker | P2: Checker | Q2: Approval
N3: Finish Date | O3: 45243 | P3: 45243 | Q3: 45243
B5: Request date | F5: 45149 | J5: Test site | N5: GN QM
B6: Product group | F6: Speaker | J6: Tester | N6: MÃ THỊ HỒNG DUYÊN
B7: Product name | F7: BRS 161014S08ZZ | J7: Department | N7: Reliability
B8: Test reason | J8: Temperature & Hummidity | N8: 26℃ / 48%
B9: Test period | F9: 8.11.2023-13.11.2023 | J9: Sample q'ty | N9: 30EA
B10: 1. TEST ITEM AND CONDITION
B11: Test item | F11: Sample q'ty | G11: Test condition | N11: Starting date | O11: Ending date | P11: Test result | Q11: Note
B12: High temp and humidity 1 | F12: 10 | G12: Temperature: 60℃ ± 5℃, Humidity: 90% ± 5% Time: 120Hrs | N12: 45238 | O12: 45243 | P12: PASS
B13: Load test (Max 80%) | F13: 10 | G13: White Noise (EIA Filter), at Max Power 80% (3.1Vrms) 24Hr | N13: 45238 | O13: 45239 | P13: PASS
B14: Combine Drop test | D14: Continuously drop | F14: 10 | G14: Height:80cm, Cycle:100 times, ground:10mm Steel , JIG 300g | N14: 45239 | O14: 45239 | P14: PASS
D15: Freely drop | G15: Height:152cm, Cycle:24 times, ground:25mm Steel , JIG 300g (6 sides->4 corners->4 edges->6 sides->4 corners) | N15: 45239 | O15: 45239 | P15: NG 2/11 | Q15: N01,6 NOISE
B16: ※ SPEC
B17: - Speaker: 116.8 ± 2dB at 800 ,1.kHz , 1180kHz , 1500kHz
B18: 2. TEST DATA
B19: ITEM | E19: SPK | P19: HEARING
E21: SPL | H21: IMPEDANCE | K21: F0 | N21: THD
B22: STANDARD | E22: 116.8 ± 2dB | H22: 8Ω ± 15% at 2kHz (3.1V) | K22: 890 ± 120Hz at 3.1V | N22: 100Hz 25%,200Hz 22%, 300Hz 26%, 500Hz 21%,1KHz 8%, 2KHz ~4KHz 3%, 3000Hz 3%,5KHz 5%, 9KHz 5%, 10KHz~14KHz 2%, with 3.1V
E23: 114.8dB - 118.8dB | H23: 6.8Ω - 9.2Ω | K23: 770Hz - 1010Hz
B24: Reliability test items | D24: NO | E24: Before | F24: After | G24: Deviation | H24: Before | I24: After | J24: Deviation | K24: Before | L24: After | M24: Deviation | N24: After | O24: Deviation | P24: Before | Q24: After
B25: High temp and humidity 60 - 90 | D25: 1 | E25: 116.53284 | F25: 116.52508 | G25: -0.0077675 | H25: 7.54195 | I25: 7.45742 | J25: -0.08453 | K25: 938.16906 | L25: 927.04728 | M25: 11.12178 | N25: OK | O25: OK | P25: OK | Q25: OK
D26: 2 | E26: 116.44405 | F26: 116.4674 | G26: 0.02335 | H26: 7.25521 | I26: 7.16612 | J26: -0.08909 | K26: 923.37676 | L26: 919.96066 | M26: 3.4161 | N26: OK | O26: OK | P26: OK | Q26: OK
D27: 3 | E27: 116.19854 | F27: 116.44069 | G27: 0.2421425 | H27: 7.17562 | I27: 7.0665 | J27: -0.10912 | K27: 934.4295 | L27: 945.51418 | M27: -11.08468 | N27: OK | O27: OK | P27: OK | Q27: OK
D28: 4 | E28: 116.30175 | F28: 116.64681 | G28: 0.34506 | H28: 7.23088 | I28: 7.19017 | J28: -0.04071 | K28: 920.4513 | L28: 941.07186 | M28: -20.62056 | N28: OK | O28: OK | P28: OK | Q28: OK
D29: 5 | E29: 116.17985 | F29: 116.05339 | G29: -0.1264575 | H29: 7.17721 | I29: 7.22722 | J29: 0.05001 | K29: 942.19522 | L29: 923.53312 | M29: 18.6621 | N29: OK | O29: OK | P29: OK | Q29: OK
D30: 6 | E30: 115.0719 | F30: 115.24763 | G30: 0.17573 | H30: 7.25474 | I30: 6.9059 | J30: -0.34884 | K30: 933.02201 | L30: 926.65689 | M30: 6.36512 | N30: OK | O30: OK | P30: OK | Q30: OK
D31: 7 | E31: 115.28637 | F31: 115.33176 | G31: 0.04539 | H31: 7.15303 | I31: 7.3189 | J31: 0.16587 | K31: 923.15871 | L31: 917.25137 | M31: 5.90734 | N31: OK | O31: OK | P31: OK | Q31: OK
D32: 8 | E32: 115.06929 | F32: 115.12511 | G32: 0.0558125 | H32: 7.18865 | I32: 7.23574 | J32: 0.04709 | K32: 915.81283 | L32: 928.6188 | M32: -12.80597 | N32: OK | O32: OK | P32: OK | Q32: OK
D33: 9 | E33: 115.47705 | F33: 115.47983 | G33: 0.00278 | H33: 7.11079 | I33: 7.4707 | J33: 0.35991 | K33: 942.27094 | L33: 918.14146 | M33: 24.12948 | N33: OK | O33: OK | P33: OK | Q33: OK
D34: 10 | E34: 115.41164 | F34: 115.30085 | G34: -0.1107875 | H34: 7.18248 | I34: 7.11603 | J34: -0.06645 | K34: 935.33132 | L34: 934.36494 | M34: 0.96638 | N34: OK | O34: OK | P34: OK | Q34: OK
B35: Load test Max 80% | D35: 1 | E35: 115.76306 | F35: 116.64734 | G35: 0.8842775 | H35: 7.16442 | I35: 6.91019 | J35: -0.25423 | K35: 917.66596 | L35: 861.98839 | M35: 55.67757 | N35: OK | O35: OK | P35: OK | Q35: OK
D36: 2 | E36: 115.63137 | F36: 116.39845 | G36: 0.7670875 | H36: 7.12896 | I36: 7.33776 | J36: 0.2088 | K36: 895.04773 | L36: 915.85586 | M36: -20.80813 | N36: OK | O36: OK | P36: OK | Q36: OK
D37: 3 | E37: 115.81059 | F37: 115.72899 | G37: -0.081595 | H37: 7.193 | I37: 7.1534 | J37: -0.0396 | K37: 929.82127 | L37: 931.59214 | M37: -1.77087 | N37: OK | O37: OK | P37: OK | Q37: OK
D38: 4 | E38: 116.32336 | F38: 116.23786 | G38: -0.085505 | H38: 7.19411 | I38: 7.06301 | J38: -0.1311 | K38: 892.80693 | L38: 899.75492 | M38: -6.94799 | N38: OK | O38: OK | P38: OK | Q38: OK
D39: 5 | E39: 116.3766 | F39: 116.45971 | G39: 0.0831125 | H39: 7.17991 | I39: 7.22941 | J39: 0.0495 | K39: 869.28657 | L39: 909.35141 | M39: -40.06484 | N39: OK | O39: OK | P39: OK | Q39: OK
D40: 6 | E40: 115.49076 | F40: 116.07514 | G40: 0.58438 | H40: 7.14264 | I40: 6.96543 | J40: -0.17721 | K40: 920.387 | L40: 907.27541 | M40: 13.11159 | N40: OK | O40: OK | P40: OK | Q40: OK
D41: 7 | E41: 116.33707 | F41: 115.88975 | G41: -0.44732 | H41: 7.21145 | I41: 7.16554 | J41: -0.04591 | K41: 913.21706 | L41: 915.22497 | M41: -2.00791 | N41: OK | O41: OK | P41: OK | Q41: OK
D42: 8 | E42: 116.35412 | F42: 115.48708 | G42: -0.8670375 | H42: 7.05796 | I42: 6.96161 | J42: -0.09635 | K42: 888.14756 | L42: 914.99313 | M42: -26.84557 | N42: OK | O42: OK | P42: OK | Q42: OK
D43: 9 | E43: 116.36807 | F43: 116.51126 | G43: 0.143185 | H43: 7.16242 | I43: 6.98228 | J43: -0.18014 | K43: 904.88942 | L43: 918.23683 | M43: -13.34741 | N43: OK | O43: OK | P43: OK | Q43: OK
...

Sheet Temp and humid 60-90
N1: SPL RAW DATA | AJ1: THD RAW DATA | BF1: IMPEDANCE RAW DATA
N2: SPL specification / Thông số kĩ thuật SPL | S2: SPK :116.8 dB±2dB Average of frequency 0.8, 1.0, 1.2k, 1.5k, 3.1Vrms | AJ2: THD Limit / Giới hạn THD | AO2: 100Hz 25%,200Hz 22%, 300Hz 26%, 500Hz 21%,1KHz 8%, 2KHz ~4KHz 3%, 3000Hz 3%,5KHz 5%, 9KHz 5%, 10KHz~14KHz 2%, with 3.1V | BF2: Imp / F0 Limit / Giới hạn Imp / F0 | BK2: IMP:8 Ω ±15% at 2kHz, 3.58V , F0: 890 ± 120Hz at 3.1V
N3: Evalution standard / Tiêu chuẩn đánh giá | S3: Deviation before test and after test is under ± 2db, and SPL Average value in limit / Độ lệch trước khi kiểm tra và sau khi kiểm tra nhỏ hơn ± 2db và SPL Giá trị trung bình trong giới hạn | AJ3: Evalution standard / Tiêu chuẩn đánh giá | AO3: THD value in limit / Giá trị THD trong giới hạn | BF3: Evalution standard / Tiêu chuẩn đánh giá | BK3: Value in limit / Giá trị trong giới hạn
N4: Test condition / Điều kiện kiểm tra | S4: Temperature: 60℃ ± 5℃, Humidity: 90% ± 5% Time: 120Hrs | AJ4: Test condition / Điều kiện kiểm tra | AO4: =S4 | BF4: Test condition / Điều kiện kiểm tra | BK4: =S4
N5: Sample No | O5: #1 | Q5: #2 | S5: #3 | U5: #4 | W5: #5 | Y5: #6 | AA5: #7 | AC5: #8 | AE5: #9 | AG5: #10 | AJ5: Sample No | AK5: #1 | AM5: #2 | AO5: #3 | AQ5: #4 | AS5: #5 | AU5: #6 | AW5: #7 | AY5: #8 | BA5: #9 | BC5: #10 | BF5: Sample No | BG5: #1 | BI5: #2 | BK5: #3 | BM5: #4 | BO5: #5 | BQ5: #6 | BS5: #7 | BU5: #8 | BW5: #9 | BY5: #10
N6: Result | O6: =IF(AND(O102<=118.8,O102>=114.8),"OK","NG") | P6: =IF(AND(P102<=118.8,P102>=114.8),"OK","NG") | Q6: =IF(AND(Q102<=118.8,Q102>=114.8),"OK","NG") | R6: =IF(AND(R102<=118.8,R102>=114.8),"OK","NG") | S6: =IF(AND(S102<=118.8,S102>=114.8),"OK","NG") | T6: =IF(AND(T102<=118.8,T102>=114.8),"OK","NG") | U6: =IF(AND(U102<=118.8,U102>=114.8),"OK","NG") | V6: =IF(AND(V102<=118.8,V102>=114.8),"OK","NG") | ... AH6: =IF(AND(AH102<=118.8,AH102>=114.8),"OK","NG") | BG6: =IF(AND(BG60<=9.2,BG60>=6.8),"OK","NG") | BH6: =IF(AND(BH60<=9.2,BH60>=6.8),"OK","NG") | BI6: =IF(AND(BI60<=9.2,BI60>=6.8),"OK","NG") | BJ6: =IF(AND(BJ60<=9.2,BJ60>=6.8),"OK","NG") | BK6: =IF(AND(BK60<=9.2,BK60>=6.8),"OK","NG") | BL6: =IF(AND(BL60<=9.2,BL60>=6.8),"OK","NG") | BM6: =IF(AND(BM60<=9.2,BM60>=6.8),"OK","NG") | BN6: =IF(AND(BN60<=9.2,BN60>=6.8),"OK","NG") | ... BZ6: =IF(AND(BZ60<=9.2,BZ60>=6.8),"OK","NG")
O7: Before #1 | P7: After #1 | Q7: Before #2 | R7: After #2 | S7: Before #3 | T7: After #3 | U7: Before #4 | V7: After #4 | W7: Before #5 | X7: After #5 | Y7: Before #6 | Z7: After #6 | AA7: Before #7 | AB7: After #7 | AC7: Before #8 | AD7: After #8 | AE7: Before #9 | AF7: After #9 | AG7: Before #10 | AH7: After #10 | AK7: Before #1 | AL7: After #1 | AM7: Before #2 | AN7: After #2 | AO7: Before #3 | AP7: After #3 | AQ7: Before #4 | AR7: After #4 | AS7: Before #5 | AT7: After #5 | AU7: Before #6 | AV7: After #6 | AW7: Before #7 | AX7: After #7 | AY7: Before #8 | AZ7: After #8 | BA7: Before #9 | BB7: After #9 | BC7: Before #10 | BD7: After #10 | BG7: Before #1 | BH7: After #1 | BI7: Before #2 | BJ7: After #2 | BK7: Before #3 | BL7: After #3 | BM7: Before #4 | BN7: After #4 | BO7: Before #5 | BP7: After #5 | BQ7: Before #6 | BR7: After #6 | BS7: Before #7 | BT7: After #7 | BU7: Before #8 | BV7: After #8 | BW7: Before #9 | BX7: After #9 | BY7: Before #10 | BZ7: After #10
N8: 100 | O8: 71.04579 | P8: 71.30079 | Q8: 71.15867 | R8: 71.40908 | S8: 70.80068 | T8: 70.81856 | U8: 70.50178 | V8: 71.3133 | W8: 70.2626 | X8: 70.78868 | Y8: 71.47379 | Z8: 70.94195 | AA8: 71.60356 | AB8: 71.96893 | AC8: 71.25582 | AD8: 71.09201 | AE8: 70.41993 | AF8: 70.93568 | AG8: 71.33403 | AH8: 71.40004 | AJ8: 100 | AK8: 13.5245 | AL8: 14.01858 | AM8: 17.24517 | AN8: 10.41388 | AO8: 11.52275 | AP8: 7.51629 | AQ8: 9.28782 | AR8: 9.65179 | AS8: 9.64494 | AT8: 11.05348 | AU8: 11.17282 | AV8: 11.04534 | AW8: 16.10451 | AX8: 8.14932 | AY8: 16.71202 | AZ8: 9.9997 | BA8: 18.55279 | BB8: 8.18378 | BC8: 9.90636 | BD8: 13.27592 | BF8: 100 | BG8: 6.90396 | BH8: 6.63717 | BI8: 6.45331 | BJ8: 6.47101 | BK8: 6.44591 | BL8: 6.3981 | BM8: 6.51839 | BN8: 6.55419 | BO8: 6.3878 | BP8: 6.56044 | BQ8: 6.43975 | BR8: 6.16583 | BS8: 6.60184 | BT8: 6.67514 | BU8: 6.65624 | BV8: 6.672 | BW8: 6.36525 | BX8: 7.15076 | BY8: 6.50949 | BZ8: 6.37935
N9: 106 | O9: 71.3489 | P9: 71.75056 | Q9: 71.62861 | R9: 71.90904 | S9: 71.26219 | T9: 71.27552 | U9: 70.92137 | V9: 71.81852 | W9: 70.7894 | X9: 71.3312 | Y9: 71.52457 | Z9: 70.87724 | AA9: 71.69756 | AB9: 71.83685 | AC9: 71.22788 | AD9: 70.92893 | AE9: 70.80337 | AF9: 71.52873 | AG9: 70.89693 | AH9: 71.52335 | AJ9: 106 | AK9: 13.48678 | AL9: 13.57616 | AM9: 16.63565 | AN9: 10.25395 | AO9: 11.39859 | AP9: 7.40238 | AQ9: 9.21627 | AR9: 9.61208 | AS9: 9.68543 | AT9: 11.11514 | AU9: 11.2078 | AV9: 11.00913 | AW9: 16.29326 | AX9: 8.38106 | AY9: 15.64341 | AZ9: 10.11665 | BA9: 18.22844 | BB9: 8.25988 | BC9: 9.78479 | BD9: 13.48145 | BF9: 106 | BG9: 6.98396 | BH9: 6.70215 | BI9: 6.53612 | BJ9: 6.55627 | BK9: 6.53039 | BL9: 6.47484 | BM9: 6.59862 | BN9: 6.64126 | BO9: 6.47165 | BP9: 6.64199 | BQ9: 6.52603 | BR9: 6.25377 | BS9: 6.69759 | BT9: 6.7449 | BU9: 6.7501 | BV9: 6.72036 | BW9: 6.45096 | BX9: 7.16965 | BY9: 6.5926 | BZ9: 6.4456
N10: 112 | O10: 71.88348 | P10: 72.25202 | Q10: 72.17923 | R10: 72.41999 | S10: 71.76806 | T10: 71.79716 | U10: 71.44828 | V10: 72.30137 | W10: 71.34982 | X10: 71.84234 | Y10: 71.78841 | Z10: 71.15505 | AA10: 71.89248 | AB10: 72.08724 | AC10: 71.52241 | AD10: 71.2582 | AE10: 71.19943 | AF10: 72.09108 | AG10: 70.89599 | AH10: 71.84641 | AJ10: 112 | AK10: 13.20991 | AL10: 13.29645 | AM10: 16.15702 | AN10: 10.1132 | AO10: 11.2989 | AP10: 7.2825 | AQ10: 9.26949 | AR10: 9.58004 | AS10: 9.69971 | AT10: 11.17239 | AU10: 11.23541 | AV10: 11.01544 | AW10: 16.28253 | AX10: 8.53291 | AY10: 14.89056 | AZ10: 10.10636 | BA10: 17.99848 | BB10: 8.30347 | BC10: 9.68191 | BD10: 13.68858 | BF10: 112 | BG10: 7.04548 | BH10: 6.74387 | BI10: 6.6009 | BJ10: 6.62357 | BK10: 6.59583 | BL10: 6.52475 | BM10: 6.66084 | BN10: 6.66663 | BO10: 6.537 | BP10: 6.64342 | BQ10: 6.59323 | BR10: 6.32207 | BS10: 6.7747 | BT10: 6.80069 | BU10: 6.82401 | BV10: 6.68935 | BW10: 6.5179 | BX10: 7.20499 | BY10: 6.6576 | BZ10: 6.51046
N11: 118 | O11: 72.80152 | P11: 73.16418 | Q11: 73.0928 | R11: 73.3234 | S11: 72.68018 | T11: 72.72462 | U11: 72.40752 | V11: 73.2004 | W11: 72.27508 | X11: 72.71819 | Y11: 72.24134 | Z11: 71.66463 | AA11: 72.19191 | AB11: 72.50345 | AC11: 71.98801 | AD11: 71.81588 | AE11: 71.90911 | AF11: 72.82789 | AG11: 71.51388 | AH11: 72.41735 | AJ11: 118 | AK11: 13.01706 | AL11: 13.04248 | AM11: 15.90133 | AN11: 9.98068 | AO11: 11.18099 | AP11: 7.20871 | AQ11: 9.29041 | AR11: 9.48099 | AS11: 9.70797 | AT11: 11.22747 | AU11: 11.26489 | AV11: 10.89439 | AW11: 16.28741 | AX11: 8.557 | AY11: 14.41786 | AZ11: 10.19218 | BA11: 17.68605 | BB11: 8.35367 | BC11: 9.6281 | BD11: 13.72669 | BF11: 118 | BG11: 7.0943 | BH11: 6.77574 | BI11: 6.65512 | BJ11: 6.67661 | BK11: 6.65017 | BL11: 6.57458 | BM11: 6.7122 | BN11: 6.72112 | BO11: 6.59151 | BP11: 6.70165 | BQ11: 6.64748 | BR11: 6.37676 | BS11: 6.83502 | BT11: 6.8495 | BU11: 6.88481 | BV11: 6.73125 | BW11: 6.57418 | BX11: 7.2821 | BY11: 6.71299 | BZ11: 6.56297
N12: 125 | O12: 73.84113 | P12: 74.16191 | Q12: 74.10543 | R12: 74.3175 | S12: 73.66263 | T12: 73.70554 | U12: 73.39256 | V12: 74.16551 | W12: 73.33287 | X12: 73.78503 | Y12: 72.78492 | Z12: 72.5075 | AA12: 72.88961 | AB12: 72.9635 | AC12: 72.63481 | AD12: 72.45161 | AE12: 72.79216 | AF12: 73.51042 | AG12: 72.27749 | AH12: 72.98566 | AJ12: 125 | AK12: 12.81276 | AL12: 12.77218 | AM12: 15.66562 | AN12: 9.83918 | AO12: 11.06839 | AP12: 7.13209 | AQ12: 9.2895 | AR12: 9.37628 | AS12: 9.7031 | AT12: 11.29562 | AU12: 11.31321 | AV12: 10.76217 | AW12: 16.32554 | AX12: 8.57306 | AY12: 13.96586 | AZ12: 10.23862 | BA12: 17.35377 | BB12: 8.42032 | BC12: 9.58993 | BD12: 13.83024 | BF12: 125 | BG12: 7.14304 | BH12: 6.79311 | BI12: 6.70786 | BJ12: 6.72813 | BK12: 6.70086 | BL12: 6.62918 | BM12: 6.7619 | BN12: 6.77385 | BO12: 6.64453 | BP12: 6.75134 | BQ12: 6.69985 | BR12: 6.42998 | BS12: 6.89517 | BT12: 6.89939 | BU12: 6.94564 | BV12: 6.77773 | BW12: 6.62933 | BX12: 7.33669 | BY12: 6.7646 | BZ12: 6.61235
N13: 132 | O13: 74.98666 | P13: 75.27688 | Q13: 75.23169 | R13: 75.43148 | S13: 74.79505 | T13: 74.79541 | U13: 74.52578 | V13: 75.24359 | W13: 74.56542 | X13: 74.95856 | Y13: 73.4302 | Z13: 73.43502 | AA13: 73.92531 | AB13: 73.80203 | AC13: 73.64448 | AD13: 73.31178 | AE13: 73.78305 | AF13: 74.40554 | AG13: 73.20415 | AH13: 73.85745 | AJ13: 132 | AK13: 12.38163 | AL13: 11.95421 | AM13: 15.79279 | AN13: 9.58097 | AO13: 10.98008 | AP13: 7.10331 | AQ13: 9.28589 | AR13: 9.14064 | AS13: 9.68051 | AT13: 11.38027 | AU13: 11.40123 | AV13: 10.78775 | AW13: 16.5216 | AX13: 8.69149 | AY13: 13.37291 | AZ13: 10.549 | BA13: 16.75571 | BB13: 8.43052 | BC13: 9.6108 | BD13: 14.03568 | BF13: 132 | BG13: 7.18391 | BH13: 6.82909 | BI13: 6.75174 | BJ13: 6.76823 | BK13: 6.74256 | BL13: 6.67128 | BM13: 6.80515 | BN13: 6.79375 | BO13: 6.68862 | BP13: 6.79479 | BQ13: 6.7434 | BR13: 6.47531 | BS13: 6.94608 | BT13: 6.94073 | BU13: 6.9946 | BV13: 6.81845 | BW13: 6.67396 | BX13: 7.33528 | BY13: 6.80771 | BZ13: 6.65568
N14: 140 | O14: 76.35282 | P14: 76.53795 | Q14: 76.44561 | R14: 76.64983 | S14: 76.00284 | T14: 76.0354 | U14: 75.8015 | V14: 76.42459 | W14: 75.82908 | X14: 76.18123 | Y14: 74.54526 | Z14: 74.81158 | AA14: 75.03559 | AB14: 75.04468 | AC14: 74.85498 | AD14: 74.52606 | AE14: 74.71787 | AF14: 75.32642 | AG14: 74.73843 | AH14: 74.91863 | AJ14: 140 | AK14: 12.14647 | AL14: 11.59191 | AM14: 16.01602 | AN14: 9.32578 | AO14: 10.79782 | AP14: 7.03163 | AQ14: 9.28883 | AR14: 8.97029 | AS14: 9.71862 | AT14: 11.40907 | AU14: 11.51933 | AV14: 10.79471 | AW14: 16.68683 | AX14: 8.84334 | AY14: 13.34658 | AZ14: 10.69759 | BA14: 16.23217 | BB14: 8.37771 | BC14: 9.66092 | BD14: 14.14209 | BF14: 140 | BG14: 7.22383 | BH14: 6.87608 | BI14: 6.79498 | BJ14: 6.81057 | BK14: 6.78263 | BL14: 6.67424 | BM14: 6.84618 | BN14: 6.82487 | BO14: 6.73062 | BP14: 6.83497 | BQ14: 6.78642 | BR14: 6.51821 | BS14: 6.99323 | BT14: 6.97857 | BU14: 7.04238 | BV14: 6.85599 | BW14: 6.71754 | BX14: 7.41721 | BY14: 6.85073 | BZ14: 6.79305
N15: 150 | O15: 77.63683 | P15: 77.79422 | Q15: 77.66377 | R15: 77.91468 | S15: 77.24447 | T15: 77.27884 | U15: 77.06016 | V15: 77.69101 | W15: 77.12982 | X15: 77.48355 | Y15: 75.70704 | Z15: 76.13376 | AA15: 76.33248 | AB15: 76.18895 | AC15: 76.0856 | AD15: 75.71115 | AE15: 75.8701 | AF15: 76.37342 | AG15: 76.20334 | AH15: 76.07701 | AJ15: 150 | AK15: 11.86267 | AL15: 11.27463 | AM15: 13.94016 | AN15: 9.1015 | AO15: 10.50579 | AP15: 6.82954 | AQ15: 9.33462 | AR15: 8.98107 | AS15: 9.81133 | AT15: 11.49681 | AU15: 11.68565 | AV15: 10.63772 | AW15: 16.60461 | AX15: 8.94233 | AY15: 10.49026 | AZ15: 10.77578 | BA15: 15.69226 | BB15: 8.2706 | BC15: 9.83144 | BD15: 14.22663 | BF15: 150 | BG15: 7.26425 | BH15: 6.91971 | BI15: 6.84128 | BJ15: 6.85441 | BK15: 6.82717 | BL15: 6.7149 | BM15: 6.88894 | BN15: 6.87123 | BO15: 6.77682 | BP15: 6.87485 | BQ15: 6.8324 | BR15: 6.56493 | BS15: 7.04236 | BT15: 7.02354 | BU15: 7.09381 | BV15: 6.89636 | BW15: 6.76408 | BX15: 7.46838 | BY15: 6.89569 | BZ15: 6.83728
N16: 160 | O16: 78.91927 | P16: 79.04955 | Q16: 78.90308 | R16: 79.19942 | S16: 78.53053 | T16: 78.54352 | U16: 78.31239 | V16: 78.9991 | W16: 78.45862 | X16: 78.80176 | Y16: 76.93864 | Z16: 77.4465 | AA16: 77.68986 | AB16: 77.46805 | AC16: 77.34485 | AD16: 76.94591 | AE16: 77.13705 | AF16: 77.57507 | AG16: 77.49018 | AH16: 77.31819 | AJ16: 160 | AK16: 11.1804 | AL16: 10.93216 | AM16: 13.55672 | AN16: 8.90278 | AO16: 10.32022 | AP16: 6.89567 | AQ16: 9.45055 | AR16: 8.87192 | AS16: 9.97755 | AT16: 11.72137 | AU16: 11.87817 | AV16: 10.23446 | AW16: 16.55326 | AX16: 8.91892 | AY16: 10.67985 | AZ16: 10.87573 | BA16: 15.18376 | BB16: 8.32421 | BC16: 9.32623 | BD16: 14.07006 | BF16: 160 | BG16: 7.29914 | BH16: 6.96255 | BI16: 6.88175 | BJ16: 6.89191 | BK16: 6.86415 | BL16: 6.7579 | BM16: 6.92608 | BN16: 6.93293 | BO16: 6.81571 | BP16: 6.91163 | BQ16: 6.87197 | BR16: 6.60448 | BS16: 7.08218 | BT16: 7.05734 | BU16: 7.13226 | BV16: 6.93129 | BW16: 6.8018 | BX16: 7.49162 | BY16: 6.93288 | BZ16: 6.84514
N17: 170 | O17: 80.21963 | P17: 80.36069 | Q17: 80.18525 | R17: 80.50078 | S17: 79.88182 | T17: 79.82192 | U17: 79.57993 | V17: 80.28713 | W17: 79.74639 | X17: 80.09232 | Y17: 78.2313 | Z17: 78.77479 | AA17: 78.94647 | AB17: 78.7263 | AC17: 78.6505 | AD17: 78.22046 | AE17: 78.36828 | AF17: 78.90291 | AG17: 78.68208 | AH17: 78.67717 | AJ17: 170 | AK17: 10.94056 | AL17: 10.75563 | AM17: 13.44248 | AN17: 8.76854 | AO17: 10.18754 | AP17: 6.99359 | AQ17: 9.57774 | AR17: 8.75698 | AS17: 10.12888 | AT17: 11.94264 | AU17: 12.10731 | AV17: 10.11473 | AW17: 16.31134 | AX17: 8.93583 | AY17: 10.86459 | AZ17: 11.02115 | BA17: 14.72459 | BB17: 8.38039 | BC17: 9.08 | BD17: 14.02291 | BF17: 170 | BG17: 7.32867 | BH17: 7.01147 | BI17: 6.9152 | BJ17: 6.92503 | BK17: 6.89474 | BL17: 6.78507 | BM17: 6.95717 | BN17: 6.95792 | BO17: 6.84821 | BP17: 6.94189 | BQ17: 6.90528 | BR17: 6.63675 | BS17: 7.11552 | BT17: 7.08296 | BU17: 7.16233 | BV17: 6.95821 | BW17: 6.83406 | BX17: 7.52508 | BY17: 6.96486 | BZ17: 6.83264
N18: 180 | O18: 81.5625 | P18: 81.70797 | Q18: 81.50842 | R18: 81.78876 | S18: 81.22764 | T18: 81.1471 | U18: 80.82675 | V18: 81.51608 | W18: 80.96357 | X18: 81.35056 | Y18: 79.52215 | Z18: 80.02613 | AA18: 80.20301 | AB18: 79.88524 | AC18: 79.96525 | AD18: 79.4985 | AE18: 79.528 | AF18: 80.20983 | AG18: 79.89139 | AH18: 79.92113 | AJ18: 180 | AK18: 10.69602 | AL18: 10.709 | AM18: 13.4205 | AN18: 8.72745 | AO18: 10.15427 | AP18: 7.158 | AQ18: 9.82037 | AR18: 8.73315 | AS18: 10.3724 | AT18: 12.18233 | AU18: 12.37994 | AV18: 10.05774 | AW18: 16.15414 | AX18: 8.93259 | AY18: 11.15534 | AZ18: 11.28437 | BA18: 14.45691 | BB18: 8.39129 | BC18: 9.10302 | BD18: 13.94073 | BF18: 180 | BG18: 7.3535 | BH18: 7.03472 | BI18: 6.9436 | BJ18: 6.95207 | BK18: 6.92103 | BL18: 6.81132 | BM18: 6.98331 | BN18: 6.96051 | BO18: 6.87637 | BP18: 6.97042 | BQ18: 6.93319 | BR18: 6.66527 | BS18: 7.14391 | BT18: 7.10679 | BU18: 7.18809 | BV18: 6.98194 | BW18: 6.86212 | BX18: 7.57564 | BY18: 6.99188 | BZ18: 6.85091
L19: Limit | N19: 190 | O19: 82.7877 | P19: 82.92399 | Q19: 82.74314 | R19: 83.02865 | S19: 82.47082 | T19: 82.35702 | U19: 82.0816 | V19: 82.75242 | W19: 82.19129 | X19: 82.57032 | Y19: 80.77301 | Z19: 81.24317 | AA19: 81.51946 | AB19: 81.12644 | AC19: 81.27173 | AD19: 80.85535 | AE19: 80.85173 | AF19: 81.48598 | AG19: 81.15233 | AH19: 81.20853 | AJ19: 190 | AK19: 10.67074 | AL19: 10.71148 | AM19: 13.49844 | AN19: 8.77623 | AO19: 10.2015 | AP19: 7.40434 | AQ19: 10.08951 | AR19: 8.77146 | AS19: 10.72789 | AT19: 12.43161 | AU19: 12.6966 | AV19: 10.06992 | AW19: 16.09045 | AX19: 9.04982 | AY19: 11.53894 | AZ19: 11.66048 | BA19: 14.28879 | BB19: 8.46803 | BC19: 9.19652 | BD19: 13.88295 | BF19: 190 | BG19: 7.37608 | BH19: 7.05569 | BI19: 6.96941 | BJ19: 6.97573 | BK19: 6.94425 | BL19: 6.83569 | BM19: 7.0068 | BN19: 6.9804 | BO19: 6.90105 | BP19: 6.99367 | BQ19: 6.95817 | BR19: 6.69031 | BS19: 7.17016 | BT19: 7.13023 | BU19: 7.21087 | BV19: 7.0032 | BW19: 6.88713 | BX19: 7.49764 | BY19: 7.01621 | BZ19: 6.87096
K20: 100 | L20: 25 | N20: 200 | O20: 83.95513 | P20: 84.09646 | Q20: 83.91592 | R20: 84.1872 | S20: 83.64232 | T20: 83.51217 | U20: 83.281 | V20: 83.90881 | W20: 83.33245 | X20: 83.72788 | Y20: 81.97099 | Z20: 82.40517 | AA20: 82.70301 | AB20: 82.32415 | AC20: 82.48174 | AD20: 82.10042 | AE20: 82.04577 | AF20: 82.70842 | AG20: 82.37003 | AH20: 82.40643 | AJ20: 200 | AK20: 10.73141 | AL20: 10.81822 | AM20: 13.59056 | AN20: 8.92308 | AO20: 10.33714 | AP20: 7.67122 | AQ20: 10.39496 | AR20: 8.92706 | AS20: 11.16451 | AT20: 12.71215 | AU20: 13.04724 | AV20: 10.2588 | AW20: 16.12042 | AX20: 9.30832 | AY20: 11.91654 | AZ20: 12.02586 | BA20: 14.30442 | BB20: 8.58791 | BC20: 9.3349 | BD20: 13.95844 | BF20: 200 | BG20: 7.3964 | BH20: 7.07852 | BI20: 6.99344 | BJ20: 6.99781 | BK20: 6.96472 | BL20: 6.86325 | BM20: 7.02721 | BN20: 7.00336 | BO20: 6.92394 | BP20: 7.01633 | BQ20: 6.98097 | BR20: 6.71213 | BS20: 7.19313 | BT20: 7.15137 | BU20: 7.23227 | BV20: 7.02229 | BW20: 6.9099 | BX20: 7.50476 | BY20: 7.03819 | BZ20: 6.88786
K21: 200 | L21: 22 | N21: 212 | O21: 85.07871 | P21: 85.21271 | Q21: 85.03484 | R21: 85.28615 | S21: 84.73852 | T21: 84.62461 | U21: 84.43666 | V21: 85.00784 | W21: 84.4277 | X21: 84.82705 | Y21: 83.14767 | Z21: 83.55513 | AA21: 83.85103 | AB21: 83.48088 | AC21: 83.68324 | AD21: 83.29201 | AE21: 83.16239 | AF21: 83.86028 | AG21: 83.51873 | AH21: 83.56202 | AJ21: 212 | AK21: 10.92781 | AL21: 11.11912 | AM21: 13.86738 | AN21: 9.21832 | AO21: 10.59471 | AP21: 8.09629 | AQ21: 10.84008 | AR21: 9.21187 | AS21: 11.72821 | AT21: 13.14289 | AU21: 13.48325 | AV21: 10.58476 | AW21: 16.2773 | AX21: 9.7155 | AY21: 12.48669 | AZ21: 12.57979 | BA21: 14.45882 | BB21: 8.83847 | BC21: 9.57309 | BD21: 14.10399 | BF21: 212 | BG21: 7.41779 | BH21: 7.10211 | BI21: 7.01883 | BJ21: 7.02142 | BK21: 6.9865 | BL21: 6.87938 | BM21: 7.04879 | BN21: 7.02595 | BO21: 6.9482 | BP21: 7.03987 | BQ21: 7.00391 | BR21: 6.73471 | BS21: 7.21833 | BT21: 7.17358 | BU21: 7.25402 | BV21: 7.04323 | BW21: 6.93278 | BX21: 7.51785 | BY21: 7.0621 | BZ21: 6.90848
K22: 300 | L22: 26 | N22: 224 | O22: 86.14128 | P22: 86.27266 | Q22: 86.09568 | R22: 86.34999 | S22: 85.77784 | T22: 85.6968 | U22: 85.55917 | V22: 86.08362 | W22: 85.50634 | X22: 85.90333 | Y22: 84.29631 | Z22: 84.63721 | AA22: 84.97101 | AB22: 84.62949 | AC22: 84.81302 | AD22: 84.46595 | AE22: 84.30462 | AF22: 84.98414 | AG22: 84.66253 | AH22: 84.66489 | AJ22: 224 | AK22: 11.2085 | AL22: 11.47286 | AM22: 14.34236 | AN22: 9.60784 | AO22: 10.91964 | AP22: 8.5576 | AQ22: 11.40115 | AR22: 9.58404 | AS22: 12.31034 | AT22: 13.71043 | AU22: 13.91013 | AV22: 10.95532 | AW22: 16.53309 | AX22: 10.23646 | AY22: 13.15621 | AZ22: 13.21002 | BA22: 14.72715 | BB22: 9.26248 | BC22: 9.92485 | BD22: 14.41893 | BF22: 224 | BG22: 7.43699 | BH22: 7.11954 | BI22: 7.03902 | BJ22: 7.04302 | BK22: 7.00631 | BL22: 6.90082 | BM22: 7.06754 | BN22: 7.04975 | BO22: 6.9709 | BP22: 7.06211 | BQ22: 7.02565 | BR22: 6.75689 | BS22: 7.24044 | BT22: 7.1938 | BU22: 7.27789 | BV22: 7.06351 | BW22: 6.95438 | BX22: 7.45191 | BY22: 7.08361 | BZ22: 6.92853
K23: 500 | L23: 21 | N23: 236 | O23: 87.13716 | P23: 87.2665 | Q23: 87.08522 | R23: 87.36776 | S23: 86.76313 | T23: 86.70127 | U23: 86.62296 | V23: 87.12091 | W23: 86.55639 | X23: 86.94866 | Y23: 85.41669 | Z23: 85.72739 | AA23: 86.06766 | AB23: 85.78825 | AC23: 85.88716 | AD23: 85.59004 | AE23: 85.42779 | AF23: 86.07725 | AG23: 85.79295 | AH23: 85.74632 | AJ23: 236 | AK23: 11.44181 | AL23: 11.81875 | AM23: 14.79451 | AN23: 9.9938 | AO23: 11.27268 | AP23: 9.0727 | AQ23: 11.97828 | AR23: 9.94141 | AS23: 12.88564 | AT23: 14.33144 | AU23: 14.31376 | AV23: 11.31519 | AW23: 16.92962 | AX23: 10.75723 | AY23: 13.77958 | AZ23: 13.85994 | BA23: 15.08366 | BB23: 9.69678 | BC23: 10.28913 | BD23: 14.78799 | BF23: 236 | BG23: 7.45509 | BH23: 7.14285 | BI23: 7.05824 | BJ23: 7.06189 | BK23: 7.02458 | BL23: 6.91915 | BM23: 7.08578 | BN23: 7.06657 | BO23: 6.98968 | BP23: 7.07997 | BQ23: 7.04585 | BR23: 6.77645 | BS23: 7.26182 | BT23: 7.20903 | BU23: 7.30024 | BV23: 7.08032 | BW23: 6.97481 | BX23: 7.47278 | BY23: 7.10274 | BZ23: 6.94647
K24: 1000 | L24: 8 | N24: 250 | O24: 88.14229 | P24: 88.28253 | Q24: 88.09451 | R24: 88.36891 | S24: 87.77239 | T24: 87.71197 | U24: 87.63967 | V24: 88.12376 | W24: 87.56309 | X24: 87.97454 | Y24: 86.45097 | Z24: 86.77807 | AA24: 87.08589 | AB24: 86.83216 | AC24: 86.87855 | AD24: 86.61409 | AE24: 86.44815 | AF24: 87.10515 | AG24: 86.82794 | AH24: 86.7744 | AJ24: 250 | AK24: 11.78614 | AL24: 12.25166 | AM24: 15.24221 | AN24: 10.3985 | AO24: 11.67265 | AP24: 9.58997 | AQ24: 12.59702 | AR24: 10.31833 | AS24: 13.39666 | AT24: 15.00757 | AU24: 14.7428 | AV24: 11.76713 | AW24: 17.30272 | AX24: 11.22069 | AY24: 14.37733 | AZ24: 14.51336 | BA24: 15.54682 | BB24: 10.09394 | BC24: 10.65313 | BD24: 15.19369 | BF24: 250 | BG24: 7.47551 | BH24: 7.15851 | BI24: 7.07942 | BJ24: 7.0823 | BK24: 7.04371 | BL24: 6.93835 | BM24: 7.10398 | BN24: 7.08377 | BO24: 7.01106 | BP24: 7.09929 | BQ24: 7.0663 | BR24: 6.79603 | BS24: 7.28533 | BT24: 7.2282 | BU24: 7.32357 | BV24: 7.09618 | BW24: 6.99496 | BX24: 7.45674 | BY24: 7.12274 | BZ24: 6.96522
K25: 2000 | L25: 3 | N25: 265 | O25: 89.27727 | P25: 89.42239 | Q25: 89.23071 | R25: 89.49668 | S25: 88.91133 | T25: 88.84825 | U25: 88.77426 | V25: 89.25198 | W25: 88.70766 | X25: 89.10581 | Y25: 87.59668 | Z25: 87.91047 | AA25: 88.20744 | AB25: 87.97296 | AC25: 88.01389 | AD25: 87.75208 | AE25: 87.58712 | AF25: 88.22997 | AG25: 87.94876 | AH25: 87.90423 | AJ25: 265 | AK25: 12.22103 | AL25: 12.73456 | AM25: 15.62111 | AN25: 10.78613 | AO25: 12.13864 | AP25: 9.94921 | AQ25: 13.05811 | AR25: 10.71629 | AS25: 13.73434 | AT25: 15.57953 | AU25: 15.14872 | AV25: 12.17629 | AW25: 17.70781 | AX25: 11.49778 | AY25: 14.72107 | AZ25: 15.08073 | BA25: 16.06204 | BB25: 10.46165 | BC25: 11.05243 | BD25: 15.65508 | BF25: 265 | BG25: 7.49494 | BH25: 7.17747 | BI25: 7.09856 | BJ25: 7.10305 | BK25: 7.06268 | BL25: 6.95854 | BM25: 7.12231 | BN25: 7.10074 | BO25: 7.03299 | BP25: 7.1203 | BQ25: 7.08633 | BR25: 6.81665 | BS25: 7.30755 | BT25: 7.2469 | BU25: 7.34498 | BV25: 7.11303 | BW25: 7.01561 | BX25: 7.53169 | BY25: 7.14179 | BZ25: 6.98373
K26: 3000 | L26: 3 | N26: 280 | O26: 90.42345 | P26: 90.57133 | Q26: 90.37705 | R26: 90.63759 | S26: 90.06028 | T26: 89.98957 | U26: 89.91747 | V26: 90.39144 | W26: 89.85569 | X26: 90.24049 | Y26: 88.74598 | Z26: 89.0436 | AA26: 89.33906 | AB26: 89.1175 | AC26: 89.14713 | AD26: 88.90298 | AE26: 88.72945 | AF26: 89.37651 | AG26: 89.09189 | AH26: 89.02889 | AJ26: 280 | AK26: 12.52748 | AL26: 13.12259 | AM26: 15.94307 | AN26: 11.04843 | AO26: 12.52017 | AP26: 10.0806 | AQ26: 13.33705 | AR26: 11.06904 | AS26: 13.84746 | AT26: 15.95241 | AU26: 15.46618 | AV26: 12.5365 | AW26: 18.15196 | AX26: 11.66604 | AY26: 14.95212 | AZ26: 15.4376 | BA26: 16.55899 | BB26: 10.67207 | BC26: 11.43503 | BD26: 16.12268 | BF26: 280 | BG26: 7.51312 | BH26: 7.19474 | BI26: 7.11684 | BJ26: 7.12167 | BK26: 7.0802 | BL26: 6.98702 | BM26: 7.13903 | BN26: 7.11802 | BO26: 7.05165 | BP26: 7.13661 | BQ26: 7.10552 | BR26: 6.83485 | BS26: 7.32912 | BT26: 7.26269 | BU26: 7.36491 | BV26: 7.12902 | BW26: 7.03349 | BX26: 7.53319 | BY26: 7.16099 | BZ26: 7.00165
K27: 4000 | L27: 3 | N27: 300 | O27: 91.60714 | P27: 91.7605 | Q27: 91.56769 | R27: 91.82019 | S27: 91.24664 | T27: 91.17221 | U27: 91.09628 | V27: 91.572 | W27: 91.04176 | X27: 91.42614 | Y27: 89.93627 | Z27: 90.2528 | AA27: 90.53597 | AB27: 90.30744 | AC27: 90.34014 | AD27: 90.0872 | AE27: 89.91292 | AF27: 90.56382 | AG27: 90.28175 | AH27: 90.2344 | AJ27: 300 | AK27: 12.80841 | AL27: 13.53928 | AM27: 16.18936 | AN27: 11.1544 | AO27: 12.91797 | AP27: 9.92536 | AQ27: 13.367 | AR27: 11.44415 | AS27: 13.64061 | AT27: 16.1822 | AU27: 15.70205 | AV27: 12.90598 | AW27: 18.65674 | AX27: 11.61575 | AY27: 14.94951 | AZ27: 15.61509 | BA27: 17.1965 | BB27: 10.73218 | BC27: 11.86911 | BD27: 16.67761 | BF27: 300 | BG27: 7.53558 | BH27: 7.21603 | BI27: 7.14019 | BJ27: 7.14478 | BK27: 7.10224 | BL27: 7.009 | BM27: 7.16032 | BN27: 7.13877 | BO27: 7.07458 | BP27: 7.15933 | BQ27: 7.12982 | BR27: 6.85805 | BS27: 7.35464 | BT27: 7.28358 | BU27: 7.39025 | BV27: 7.14955 | BW27: 7.05619 | BX27: 7.55266 | BY27: 7.18452 | BZ27: 7.02379
K28: 5000 | L28: 5 | N28: 315 | O28: 92.80467 | P28: 92.95741 | Q28: 92.77102 | R28: 93.01661 | S28: 92.44666 | T28: 92.36765 | U28: 92.31669 | V28: 92.76935 | W28: 92.24174 | X28: 92.62555 | Y28: 91.15152 | Z28: 91.45896 | AA28: 91.73954 | AB28: 91.51307 | AC28: 91.54569 | AD28: 91.30655 | AE28: 91.11557 | AF28: 91.76618 | AG28: 91.4777 | AH28: 91.44234 | AJ28: 315 | AK28: 12.98319 | AL28: 13.84212 | AM28: 16.2066 | AN28: 11.08098 | AO28: 13.16464 | AP28: 9.615 | AQ28: 13.16479 | AR28: 11.70663 | AS28: 13.24525 | AT28: 16.27275 | AU28: 15.71732 | AV28: 13.12132 | AW28: 19.03206 | AX28: 11.38687 | AY28: 14.7692 | AZ28: 15.57324 | BA28: 17.67775 | BB28: 10.62654 | BC28: 12.15153 | BD28: 17.07283 | BF28: 315 | BG28: 7.55305 | BH28: 7.23854 | BI28: 7.15632 | BJ28: 7.16219 | BK28: 7.11768 | BL28: 7.01352 | BM28: 7.17541 | BN28: 7.15554 | BO28: 7.09087 | BP28: 7.1707 | BQ28: 7.14594 | BR28: 6.87494 | BS28: 7.37462 | BT28: 7.29817 | BU28: 7.40835 | BV28: 7.16248 | BW28: 7.07252 | BX28: 7.56652 | BY28: 7.20161 | BZ28: 7.03964
K29: 9000 | L29: 5 | N29: 335 | O29: 93.99975 | P29: 94.15588 | Q29: 93.97092 | R29: 94.21505 | S29: 93.64432 | T29: 93.56851 | U29: 93.53542 | V29: 93.96753 | W29: 93.44521 | X29: 93.82048 | Y29: 92.37152 | Z29: 92.66411 | AA29: 92.94621 | AB29: 92.72116 | AC29: 92.77127 | AD29: 92.52407 | AE29: 92.35191 | AF29: 92.98055 | AG29: 92.68366 | AH29: 92.65065 | AJ29: 335 | AK29: 13.1627 | AL29: 14.24392 | AM29: 16.00901 | AN29: 10.78506 | AO29: 13.46018 | AP29: 9.04955 | AQ29: 12.75407 | AR29: 12.03899 | AS29: 12.44965 | AT29: 16.30146 | AU29: 15.49532 | AV29: 13.32058 | AW29: 19.36727 | AX29: 10.87056 | AY29: 14.37565 | AZ29: 15.36404 | BA29: 18.38524 | BB29: 10.34545 | BC29: 12.50408 | BD29: 17.56082 | BF29: 335 | BG29: 7.57337 | BH29: 7.31345 | BI29: 7.17567 | BJ29: 7.18248 | BK29: 7.13783 | BL29: 7.04665 | BM29: 7.19479 | BN29: 7.17296 | BO29: 7.11094 | BP29: 7.19277 | BQ29: 7.16675 | BR29: 6.89522 | BS29: 7.40035 | BT29: 7.3203 | BU29: 7.43297 | BV29: 7.18047 | BW29: 7.09334 | BX29: 7.58323 | BY29: 7.22321 | BZ29: 7.05932
K30: 10000 | L30: 2 | N30: 355 | O30: 95.18841 | P30: 95.34895 | Q30: 95.16471 | R30: 95.41056 | S30: 94.83527 | T30: 94.76406 | U30: 94.75066 | V30: 95.16064 | W30: 94.64052 | X30: 95.01918 | Y30: 93.59149 | Z30: 93.89475 | AA30: 94.17087 | AB30: 93.94615 | AC30: 93.99233 | AD30: 93.7183 | AE30: 93.56638 | AF30: 94.20066 | AG30: 93.90593 | AH30: 93.86882 | AJ30: 355 | AK30: 13.31889 | AL30: 14.56196 | AM30: 15.58478 | AN30: 10.34469 | AO30: 13.67323 | AP30: 8.33562 | AQ30: 12.19193 | AR30: 12.34183 | AS30: 11.487 | AT30: 16.09847 | AU30: 15.05552 | AV30: 13.44343 | AW30: 19.49682 | AX30: 10.26553 | AY30: 13.75024 | AZ30: 14.96948 | BA30: 19.11314 | BB30: 9.93251 | BC30: 12.79755 | BD30: 17.9112 | BF30: 355 | BG30: 7.59408 | BH30: 7.27071 | BI30: 7.19527 | BJ30: 7.20402 | BK30: 7.15697 | BL30: 7.05653 | BM30: 7.21456 | BN30: 7.19276 | BO30: 7.12987 | BP30: 7.21139 | BQ30: 7.18699 | BR30: 6.91563 | BS30: 7.42511 | BT30: 7.33862 | BU30: 7.45711 | BV30: 7.19804 | BW30: 7.11311 | BX30: 7.53552 | BY30: 7.24443 | BZ30: 7.07786
K31: 14000 | L31: 2 | N31: 375 | O31: 96.40564 | P31: 96.5748 | Q31: 96.39246 | R31: 96.63616 | S31: 96.05666 | T31: 95.99271 | U31: 95.99444 | V31: 96.38131 | W31: 95.86575 | X31: 96.24521 | Y31: 94.84185 | Z31: 95.15084 | AA31: 95.4193 | AB31: 95.19605 | AC31: 95.23972 | AD31: 94.96553 | AE31: 94.87918 | AF31: 95.44858 | AG31: 95.14881 | AH31: 95.11798 | AJ31: 375 | AK31: 13.42731 | AL31: 14.77423 | AM31: 14.9791 | AN31: 9.79928 | AO31: 13.76658 | AP31: 7.54381 | AQ31: 11.3923 | AR31: 12.56945 | AS31: 10.37316 | AT31: 15.57337 | AU31: 14.46279 | AV31: 13.46241 | AW31: 19.43536 | AX31: 9.56227 | AY31: 12.83535 | AZ31: 14.31601 | BA31: 19.70056 | BB31: 9.4445 | BC31: 13.00474 | BD31: 18.10097 | BF31: 375 | BG31: 7.61495 | BH31: 7.32756 | BI31: 7.21542 | BJ31: 7.22542 | BK31: 7.17651 | BL31: 7.08719 | BM31: 7.23501 | BN31: 7.21139 | BO31: 7.15059 | BP31: 7.23164 | BQ31: 7.20829 | BR31: 6.93584 | BS31: 7.44974 | BT31: 7.35834 | BU31: 7.48111 | BV31: 7.21549 | BW31: 7.13365 | BX31: 7.55232 | BY31: 7.26627 | BZ31: 7.097
N32: 400 | O32: 97.62324 | P32: 97.79672 | Q32: 97.61946 | R32: 97.85518 | S32: 97.27451 | T32: 97.21683 | U32: 97.23209 | V32: 97.59704 | W32: 97.08691 | X32: 97.46496 | Y32: 96.07759 | Z32: 96.3856 | AA32: 96.64571 | AB32: 96.43795 | AC32: 96.47116 | AD32: 96.20177 | AE32: 96.16492 | AF32: 96.68486 | AG32: 96.37705 | AH32: 96.34444 | AJ32: 400 | AK32: 13.48831 | AL32: 14.89941 | AM32: 14.11619 | AN32: 9.09802 | AO32: 13.79309 | AP32: 6.56528 | AQ32: 10.15841 | AR32: 12.78994 | AS32: 8.85169 | AT32: 14.49319 | AU32: 13.54701 | AV32: 13.36381 | AW32: 19.12536 | AX32: 8.68806 | AY32: 11.44432 | AZ32: 13.14718 | BA32: 20.01703 | BB32: 8.84187 | BC32: 13.16588 | BD32: 18.16335 | BF32: 400 | BG32: 7.64304 | BH32: 7.35456 | BI32: 7.24053 | BJ32: 7.25374 | BK32: 7.20196 | BL32: 7.11193 | BM32: 7.26052 | BN32: 7.23749 | BO32: 7.17641 | BP32: 7.25821 | BQ32: 7.2334 | BR32: 6.9616 | BS32: 7.48175 | BT32: 7.38379 | BU32: 7.51105 | BV32: 7.23878 | BW32: 7.16134 | BX32: 7.57313 | BY32: 7.29461 | BZ32: 7.12129
N33: 425 | O33: 98.83713 | P33: 99.0174 | Q33: 98.8462 | R33: 99.07156 | S33: 98.49005 | T33: 98.43989 | U33: 98.45902 | V33: 98.80954 | W33: 98.30494 | X33: 98.68668 | Y33: 97.30422 | Z33: 97.61587 | AA33: 97.87117 | AB33: 97.67943 | AC33: 97.70177 | AD33: 97.42546 | AE33: 97.44824 | AF33: 97.91867 | AG33: 97.60231 | AH33: 97.5687 | AJ33: 425 | AK33: 13.43562 | AL33: 14.87047 | AM33: 13.35257 | AN33: 8.4672 | AO33: 13.74179 | AP33: 5.71135 | AQ33: 8.84166 | AR33: 12.92289 | AS33: 7.44765 | AT33: 13.15682 | AU33: 12.49223 | AV33: 13.19225 | AW33: 18.68487 | AX33: 7.93946 | AY33: 10.01619 | AZ33: 11.824 | BA33: 19.88435 | BB33: 8.33687 | BC33: 13.2666 | BD33: 18.0457 | BF33: 425 | BG33: 7.67359 | BH33: 7.31938 | BI33: 7.26592 | BJ33: 7.28394 | BK33: 7.22944 | BL33: 7.13699 | BM33: 7.28762 | BN33: 7.26292 | BO33: 7.20356 | BP33: 7.2853 | BQ33: 7.25986 | BR33: 6.98712 | BS33: 7.51383 | BT33: 7.4097 | BU33: 7.54252 | BV33: 7.26257 | BW33: 7.18981 | BX33: 7.59405 | BY33: 7.32391 | BZ33: 7.1459
N34: 450 | O34: 100.04216 | P34: 100.23111 | Q34: 100.06714 | R34: 100.28121 | S34: 99.69714 | T34: 99.65636 | U34: 99.67933 | V34: 100.01518 | W34: 99.51313 | X34: 99.90354 | Y34: 98.52911 | Z34: 98.84197 | AA34: 99.09431 | AB34: 98.91863 | AC34: 98.92653 | AD34: 98.64872 | AE34: 98.71015 | AF34: 99.14907 | AG34: 98.82106 | AH34: 98.78832 | AJ34: 450 | AK34: 13.31837 | AL34: 14.69098 | AM34: 12.6147 | AN34: 7.90561 | AO34: 13.55446 | AP34: 5.027 | AQ34: 7.58577 | AR34: 12.9361 | AS34: 6.27011 | AT34: 11.74199 | AU34: 11.34565 | AV34: 12.92836 | AW34: 18.0915 | AX34: 7.29086 | AY34: 8.66055 | AZ34: 10.45959 | BA34: 19.40359 | BB34: 7.91033 | BC34: 13.24719 | BD34: 17.73608 | BF34: 450 | BG34: 7.70614 | BH34: 7.35798 | BI34: 7.29236 | BJ34: 7.31619 | BK34: 7.25846 | BL34: 7.15526 | BM34: 7.31619 | BN34: 7.28912 | BO34: 7.23284 | BP34: 7.30875 | BQ34: 7.28814 | BR34: 7.01409 | BS34: 7.54784 | BT34: 7.43515 | BU34: 7.57572 | BV34: 7.28685 | BW34: 7.22043 | BX34: 7.61989 | BY34: 7.35476 | BZ34: 7.1708
N35: 475 | O35: 101.27258 | P35: 101.47198 | Q35: 101.31694 | R35: 101.51927 | S35: 100.93259 | T35: 100.90216 | U35: 100.93032 | V35: 101.24836 | W35: 100.74733 | X35: 101.14343 | Y35: 99.77979 | Z35: 100.09081 | AA35: 100.33951 | AB35: 100.18263 | AC35: 100.17435 | AD35: 99.91184 | AE35: 100.00641 | AF35: 100.41062 | AG35: 100.06571 | AH35: 100.03277 | AJ35: 475 | AK35: 13.04981 | AL35: 14.34958 | AM35: 11.88314 | AN35: 7.41659 | AO35: 13.25442 | AP35: 4.53684 | AQ35: 6.46202 | AR35: 12.8345 | AS35: 5.33103 | AT35: 10.36401 | AU35: 10.14897 | AV35: 12.5667 | AW35: 17.3411 | AX35: 6.77494 | AY35: 7.4406 | AZ35: 9.1331 | BA35: 18.73595 | BB35: 7.54208 | BC35: 13.09701 | BD35: 17.21049 | BF35: 475 | BG35: 7.74254 | BH35: 7.41537 | BI35: 7.32185 | BJ35: 7.35173 | BK35: 7.291 | BL35: 7.18362 | BM35: 7.3477 | BN35: 7.31994 | BO35: 7.26453 | BP35: 7.3388 | BQ35: 7.31863 | BR35: 7.04401 | BS35: 7.58312 | BT35: 7.45949 | BU35: 7.61065 | BV35: 7.31486 | BW35: 7.25469 | BX35: 7.64592 | BY35: 7.38814 | BZ35: 7.19867
N36: 500 | O36: 102.53003 | P36: 102.73679 | Q36: 102.59122 | R36: 102.78428 | S36: 102.19195 | T36: 102.17307 | U36: 102.21509 | V36: 102.50909 | W36: 102.01281 | X36: 102.42254 | Y36: 101.05218 | Z36: 101.36563 | AA36: 101.61109 | AB36: 101.47718 | AC36: 101.45056 | AD36: 101.18768 | AE36: 101.28953 | AF36: 101.70298 | AG36: 101.3378 | AH36: 101.29856 | AJ36: 500 | AK36: 12.68081 | AL36: 13.87148 | AM36: 11.16646 | AN36: 7.00242 | AO36: 12.83734 | AP36: 4.23184 | AQ36: 5.50589 | AR36: 12.59645 | AS36: 4.58886 | AT36: 9.02337 | AU36: 8.98937 | AV36: 12.11326 | AW36: 16.46977 | AX36: 6.39258 | AY36: 6.3992 | AZ36: 7.89492 | BA36: 17.90474 | BB36: 7.21732 | BC36: 12.80301 | BD36: 16.49012 | BF36: 500 | BG36: 7.78312 | BH36: 7.44982 | BI36: 7.35444 | BJ36: 7.38835 | BK36: 7.32542 | BL36: 7.22481 | BM36: 7.38161 | BN36: 7.35262 | BO36: 7.30037 | BP36: 7.37094 | BQ36: 7.35208 | BR36: 7.07534 | BS36: 7.62023 | BT36: 7.49039 | BU36: 7.64728 | BV36: 7.34331 | BW36: 7.29239 | BX36: 7.67374 | BY36: 7.42631 | BZ36: 7.22819
N37: 530 | O37: 103.9238 | P37: 104.14084 | Q37: 104.00975 | R37: 104.19182 | S37: 103.59103 | T37: 103.57424 | U37: 103.65206 | V37: 103.91294 | W37: 103.41172 | X37: 103.83861 | Y37: 102.46497 | Z37: 102.78104 | AA37: 103.02353 | AB37: 102.92352 | AC37: 102.8691 | AD37: 102.60505 | AE37: 102.70374 | AF37: 103.14512 | AG37: 102.75685 | AH37: 102.70184 | AJ37: 530 | AK37: 12.08078 | AL37: 13.10392 | AM37: 10.35733 | AN37: 6.60058 | AO37: 12.18596 | AP37: 4.07452 | AQ37: 4.6039 | AR37: 12.12071 | AS37: 3.95638 | AT37: 7.51382 | AU37: 7.72718 | AV37: 11.44512 | AW37: 15.27893 | AX37: 6.06587 | AY37: 5.36173 | AZ37: 6.57447 | BA37: 16.70375 | BB37: 6.88561 | BC37: 12.25795 | BD37: 15.39954 | BF37: 530 | BG37: 7.83488 | BH37: 7.54117 | BI37: 7.39962 | BJ37: 7.43753 | BK37: 7.37204 | BL37: 7.26891 | BM37: 7.42732 | BN37: 7.39621 | BO37: 7.35018 | BP37: 7.41705 | BQ37: 7.39786 | BR37: 7.11956 | BS37: 7.66703 | BT37: 7.53367 | BU37: 7.69509 | BV37: 7.38368 | BW37: 7.34464 | BX37: 7.71297 | BY37: 7.47663 | BZ37: 7.26817
N38: 560 | O38: 105.30982 | P38: 105.53636 | Q38: 105.42202 | R38: 105.59166 | S38: 104.98244 | T38: 104.95951 | U38: 105.08035 | V38: 105.3104 | W38: 104.81094 | X38: 105.24134 | Y38: 103.86957 | Z38: 104.18941 | AA38: 104.424 | AB38: 104.36327 | AC38: 104.27723 | AD38: 104.01367 | AE38: 104.09891 | AF38: 104.58102 | AG38: 104.16859 | AH38: 104.09917 | AJ38: 560 | AK38: 11.34123 | AL38: 12.18449 | AM38: 9.6165 | AN38: 6.27707 | AO38: 11.41113 | AP38: 4.06377 | AQ38: 3.88968 | AR38: 11.4829 | AS38: 3.52842 | AT38: 6.15 | AU38: 6.6461 | AV38: 10.67852 | AW38: 14.02985 | AX38: 5.8343 | AY38: 4.50692 | AZ38: 5.4165 | BA38: 15.32427 | BB38: 6.5788 | BC38: 11.55683 | BD38: 14.17486 | BF38: 560 | BG38: 7.89633 | BH38: 7.59588 | BI38: 7.4535 | BJ38: 7.49601 | BK38: 7.42461 | BL38: 7.30539 | BM38: 7.48018 | BN38: 7.4475 | BO38: 7.41094 | BP38: 7.46604 | BQ38: 7.4537 | BR38: 7.16771 | BS38: 7.72132 | BT38: 7.58149 | BU38: 7.75008 | BV38: 7.43118 | BW38: 7.40556 | BX38: 7.75188 | BY38: 7.53522 | BZ38: 7.31547
N39: 600 | O39: 106.81528 | P39: 107.05052 | Q39: 106.95877 | R39: 107.10833 | S39: 106.49162 | T39: 106.46085 | U39: 106.63239 | V39: 106.82988 | W39: 106.33476 | X39: 106.76579 | Y39: 105.39707 | Z39: 105.72041 | AA39: 105.94151 | AB39: 105.93511 | AC39: 105.80328 | AD39: 105.54255 | AE39: 105.61285 | AF39: 106.14065 | AG39: 105.70369 | AH39: 105.61688 | AJ39: 600 | AK39: 10.21877 | AL39: 10.8357 | AM39: 8.73439 | AN39: 5.91981 | AO39: 10.29333 | AP39: 4.1842 | AQ39: 3.19824 | AR39: 10.48014 | AS39: 3.26348 | AT39: 4.68766 | AU39: 5.50273 | AV39: 9.59301 | AW39: 12.38855 | AX39: 5.53245 | AY39: 3.74185 | AZ39: 4.18916 | BA39: 13.4019 | BB39: 6.17573 | BC39: 10.51443 | BD39: 12.47739 | BF39: 600 | BG39: 8.00197 | BH39: 7.69519 | BI39: 7.54408 | BJ39: 7.59013 | BK39: 7.51553 | BL39: 7.38049 | BM39: 7.57048 | BN39: 7.53157 | BO39: 7.51444 | BP39: 7.54182 | BQ39: 7.55025 | BR39: 7.24908 | BS39: 7.80179 | BT39: 7.66083 | BU39: 7.83288 | BV39: 7.5071 | BW39: 7.5045 | BX39: 7.82128 | BY39: 7.63447 | BZ39: 7.39252
N40: 630 | O40: 108.38223 | P40: 108.62594 | Q40: 108.56259 | R40: 108.68342 | S40: 108.0614 | T40: 108.03433 | U40: 108.25125 | V40: 108.41524 | W40: 107.92208 | X40: 108.34981 | Y40: 106.99083 | Z40: 107.31747 | AA40: 107.51949 | AB40: 107.57945 | AC40: 107.3883 | AD40: 107.13473 | AE40: 107.19823 | AF40: 107.76373 | AG40: 107.30335 | AH40: 107.19984 | AJ40: 630 | AK40: 9.37648 | AL40: 9.84694 | AM40: 8.14339 | AN40: 5.69268 | AO40: 9.46823 | AP40: 4.30595 | AQ40: 2.86095 | AR40: 9.71145 | AS40: 3.2598 | AT40: 3.87727 | AU40: 4.82445 | AV40: 8.80373 | AW40: 11.24391 | AX40: 5.3207 | AY40: 3.4327 | AZ40: 3.51627 | BA40: 12.05475 | BB40: 5.88626 | BC40: 9.7354 | BD40: 11.26464 | BF40: 630 | BG40: 8.09927 | BH40: 7.79079 | BI40: 7.62568 | BJ40: 7.67425 | BK40: 7.59765 | BL40: 7.44955 | BM40: 7.65246 | BN40: 7.60667 | BO40: 7.61319 | BP40: 7.61161 | BQ40: 7.64134 | BR40: 7.32175 | BS40: 7.869 | BT40: 7.73356 | BU40: 7.90269 | BV40: 7.57015 | BW40: 7.59089 | BX40: 7.90578 | BY40: 7.72284 | BZ40: 7.46093
...

Sheet Load test 80%
N1: SPL RAW DATA | AJ1: THD RAW DATA | BF1: IMPEDANCE RAW DATA
N2: SPL specification / Thông số kĩ thuật SPL | S2: ='Temp and humid 60-90'!S2:X2 | AJ2: THD Limit / Giới hạn THD | AO2: ='Temp and humid 60-90'!AO2:AT2 | BF2: Imp / F0 Limit / Giới hạn Imp / F0 | BK2: ='Temp and humid 60-90'!BK2:BP2
N3: Evalution standard / Tiêu chuẩn đánh giá | S3: Deviation before test and after test is under ± 2db, and SPL Average value in limit / Độ lệch trước khi kiểm tra và sau khi kiểm tra nhỏ hơn ± 2db và SPL Giá trị trung bình trong giới hạn | AJ3: Evalution standard / Tiêu chuẩn đánh giá | AO3: THD value in limit / Giá trị THD trong giới hạn | BF3: Evalution standard / Tiêu chuẩn đánh giá | BK3: Value in limit / Giá trị trong giới hạn
N4: Test condition / Điều kiện kiểm tra | S4: White Noise (EIA Filter), at Max Power 80% (3.1Vrms) 96Hr | AJ4: Test condition / Điều kiện kiểm tra | AO4: =S4 | BF4: Test condition / Điều kiện kiểm tra | BK4: =S4
N5: Sample No | O5: #1 | Q5: #2 | S5: #3 | U5: #4 | W5: #5 | Y5: #6 | AA5: #7 | AC5: #8 | AE5: #9 | AG5: #10 | AJ5: Sample No | AK5: #1 | AM5: #2 | AO5: #3 | AQ5: #4 | AS5: #5 | AU5: #6 | AW5: #7 | AY5: #8 | BA5: #9 | BC5: #10 | BF5: Sample No | BG5: #1 | BI5: #2 | BK5: #3 | BM5: #4 | BO5: #5 | BQ5: #6 | BS5: #7 | BU5: #8 | BW5: #9 | BY5: #10
N6: Result | O6: =IF(AND(O102<=118.8,O102>=114.8),"OK","NG") | P6: =IF(AND(P102<=118.8,P102>=114.8),"OK","NG") | Q6: =IF(AND(Q102<=118.8,Q102>=114.8),"OK","NG") | R6: =IF(AND(R102<=118.8,R102>=114.8),"OK","NG") | S6: =IF(AND(S102<=118.8,S102>=114.8),"OK","NG") | T6: =IF(AND(T102<=118.8,T102>=114.8),"OK","NG") | U6: =IF(AND(U102<=118.8,U102>=114.8),"OK","NG") | V6: =IF(AND(V102<=118.8,V102>=114.8),"OK","NG") | ... AH6: =IF(AND(AH102<=118.8,AH102>=114.8),"OK","NG") | BG6: =IF(AND(BG60<=9.2,BG60>=6.8),"OK","NG") | BH6: =IF(AND(BH60<=9.2,BH60>=6.8),"OK","NG") | BI6: =IF(AND(BI60<=9.2,BI60>=6.8),"OK","NG") | BJ6: =IF(AND(BJ60<=9.2,BJ60>=6.8),"OK","NG") | BK6: =IF(AND(BK60<=9.2,BK60>=6.8),"OK","NG") | BL6: =IF(AND(BL60<=9.2,BL60>=6.8),"OK","NG") | BM6: =IF(AND(BM60<=9.2,BM60>=6.8),"OK","NG") | BN6: =IF(AND(BN60<=9.2,BN60>=6.8),"OK","NG") | ... BZ6: =IF(AND(BZ60<=9.2,BZ60>=6.8),"OK","NG")
O7: Before #1 | P7: After #1 | Q7: Before #2 | R7: After #2 | S7: Before #3 | T7: After #3 | U7: Before #4 | V7: After #4 | W7: Before #5 | X7: After #5 | Y7: Before #6 | Z7: After #6 | AA7: Before #7 | AB7: After #7 | AC7: Before #8 | AD7: After #8 | AE7: Before #9 | AF7: After #9 | AG7: Before #10 | AH7: After #10 | AK7: Before #1 | AL7: After #1 | AM7: Before #2 | AN7: After #2 | AO7: Before #3 | AP7: After #3 | AQ7: Before #4 | AR7: After #4 | AS7: Before #5 | AT7: After #5 | AU7: Before #6 | AV7: After #6 | AW7: Before #7 | AX7: After #7 | AY7: Before #8 | AZ7: After #8 | BA7: Before #9 | BB7: After #9 | BC7: Before #10 | BD7: After #10 | BG7: Before #1 | BH7: After #1 | BI7: Before #2 | BJ7: After #2 | BK7: Before #3 | BL7: After #3 | BM7: Before #4 | BN7: After #4 | BO7: Before #5 | BP7: After #5 | BQ7: Before #6 | BR7: After #6 | BS7: Before #7 | BT7: After #7 | BU7: Before #8 | BV7: After #8 | BW7: Before #9 | BX7: After #9 | BY7: Before #10 | BZ7: After #10
N8: 100 | O8: 70.2065 | P8: 71.90682 | Q8: 70.63585 | R8: 70.94868 | S8: 70.84634 | T8: 70.80113 | U8: 71.45102 | V8: 71.4694 | W8: 71.43152 | X8: 71.33424 | Y8: 69.5862 | Z8: 72.20219 | AA8: 71.42772 | AB8: 70.82885 | AC8: 70.63119 | AD8: 71.19745 | AE8: 71.48003 | AF8: 71.61497 | AG8: 70.37958 | AH8: 71.44848 | AJ8: 100 | AK8: 9.18307 | AL8: 18.18373 | AM8: 13.77236 | AN8: 8.88326 | AO8: 9.23913 | AP8: 9.1525 | AQ8: 8.42276 | AR8: 15.17774 | AS8: 9.0239 | AT8: 9.19096 | AU8: 11.54577 | AV8: 11.73869 | AW8: 10.75206 | AX8: 10.04351 | AY8: 13.18756 | AZ8: 10.68034 | BA8: 9.91951 | BB8: 11.0485 | BC8: 9.74444 | BD8: 10.45589 | BF8: 100 | BG8: 6.35081 | BH8: 6.12079 | BI8: 6.48474 | BJ8: 6.49177 | BK8: 6.37484 | BL8: 6.53555 | BM8: 6.41504 | BN8: 6.34472 | BO8: 6.35829 | BP8: 6.52397 | BQ8: 6.33595 | BR8: 6.42406 | BS8: 6.39629 | BT8: 6.65834 | BU8: 6.248 | BV8: 6.41612 | BW8: 6.38788 | BX8: 6.19809 | BY8: 6.56196 | BZ8: 6.31807
N9: 106 | O9: 70.41765 | P9: 72.32946 | Q9: 71.17594 | R9: 71.4638 | S9: 71.29303 | T9: 71.34402 | U9: 72.08201 | V9: 71.94969 | W9: 71.87404 | X9: 71.83829 | Y9: 70.38316 | Z9: 72.4399 | AA9: 71.72677 | AB9: 70.94553 | AC9: 71.28906 | AD9: 71.47901 | AE9: 71.77418 | AF9: 72.07574 | AG9: 70.86341 | AH9: 71.77958 | AJ9: 106 | AK9: 9.02177 | AL9: 17.126 | AM9: 13.16806 | AN9: 8.85751 | AO9: 9.11061 | AP9: 9.08303 | AQ9: 8.33759 | AR9: 14.76708 | AS9: 8.88533 | AT9: 9.03325 | AU9: 11.37235 | AV9: 11.53595 | AW9: 10.49617 | AX9: 9.8961 | AY9: 12.90249 | AZ9: 10.43701 | BA9: 9.7247 | BB9: 10.99862 | BC9: 9.60341 | BD9: 10.31603 | BF9: 106 | BG9: 6.43854 | BH9: 6.20639 | BI9: 6.56894 | BJ9: 6.90385 | BK9: 6.46384 | BL9: 6.6099 | BM9: 6.50127 | BN9: 6.4296 | BO9: 6.44349 | BP9: 6.60205 | BQ9: 6.42032 | BR9: 6.52449 | BS9: 6.4808 | BT9: 6.97614 | BU9: 6.33723 | BV9: 6.53908 | BW9: 6.47196 | BX9: 6.28877 | BY9: 6.64763 | BZ9: 6.40527
N10: 112 | O10: 71.1299 | P10: 72.7718 | Q10: 71.69831 | R10: 72.03704 | S10: 71.85845 | T10: 71.84714 | U10: 72.56617 | V10: 72.56117 | W10: 72.39877 | X10: 72.40805 | Y10: 70.86327 | Z10: 72.86813 | AA10: 72.33093 | AB10: 71.6102 | AC10: 72.07693 | AD10: 71.90183 | AE10: 72.25032 | AF10: 72.52866 | AG10: 71.43179 | AH10: 72.28088 | AJ10: 112 | AK10: 8.90087 | AL10: 16.30082 | AM10: 12.68661 | AN10: 8.8735 | AO10: 8.97679 | AP10: 9.0279 | AQ10: 8.26063 | AR10: 14.49573 | AS10: 9.16045 | AT10: 8.95623 | AU10: 11.47055 | AV10: 11.63888 | AW10: 10.32626 | AX10: 9.79914 | AY10: 12.68034 | AZ10: 10.30088 | BA10: 9.56546 | BB10: 10.92516 | BC10: 9.49515 | BD10: 10.16751 | BF10: 112 | BG10: 6.50539 | BH10: 6.27802 | BI10: 6.63596 | BJ10: 6.84226 | BK10: 6.53085 | BL10: 6.6673 | BM10: 6.56739 | BN10: 6.49453 | BO10: 6.51034 | BP10: 6.66331 | BQ10: 6.48639 | BR10: 6.54946 | BS10: 6.54808 | BT10: 6.97924 | BU10: 6.40501 | BV10: 6.49453 | BW10: 6.53749 | BX10: 6.35805 | BY10: 6.71399 | BZ10: 6.47079
N11: 118 | O11: 72.08985 | P11: 73.63499 | Q11: 72.67164 | R11: 73.03055 | S11: 72.94079 | T11: 72.86154 | U11: 73.51778 | V11: 73.55187 | W11: 73.41501 | X11: 73.35119 | Y11: 72.00674 | Z11: 73.81975 | AA11: 73.31932 | AB11: 72.6455 | AC11: 73.22847 | AD11: 72.66956 | AE11: 73.0803 | AF11: 73.45703 | AG11: 72.4447 | AH11: 73.30005 | AJ11: 118 | AK11: 8.82569 | AL11: 15.68388 | AM11: 12.32895 | AN11: 8.86024 | AO11: 8.90206 | AP11: 8.94382 | AQ11: 8.19498 | AR11: 14.28053 | AS11: 9.38885 | AT11: 8.8974 | AU11: 11.22436 | AV11: 11.47407 | AW11: 10.18205 | AX11: 9.72227 | AY11: 12.52565 | AZ11: 10.10483 | BA11: 9.45795 | BB11: 10.86277 | BC11: 9.41401 | BD11: 10.08771 | BF11: 118 | BG11: 6.56013 | BH11: 6.33418 | BI11: 6.68973 | BJ11: 6.86945 | BK11: 6.58595 | BL11: 6.71443 | BM11: 6.63262 | BN11: 6.54883 | BO11: 6.566 | BP11: 6.7146 | BQ11: 6.54038 | BR11: 6.60027 | BS11: 6.60474 | BT11: 7.00822 | BU11: 6.45971 | BV11: 6.63109 | BW11: 6.59145 | BX11: 6.41538 | BY11: 6.76713 | BZ11: 6.52449
N12: 125 | O12: 73.2373 | P12: 74.53658 | Q12: 73.77707 | R12: 74.11304 | S12: 73.98688 | T12: 73.96207 | U12: 74.58037 | V12: 74.55688 | W12: 74.45493 | X12: 74.35915 | Y12: 73.14536 | Z12: 74.77695 | AA12: 74.35388 | AB12: 73.7577 | AC12: 74.30411 | AD12: 73.67827 | AE12: 74.21081 | AF12: 74.469 | AG12: 73.50632 | AH12: 74.13683 | AJ12: 125 | AK12: 8.75635 | AL12: 15.00274 | AM12: 12.02432 | AN12: 8.83834 | AO12: 8.80984 | AP12: 8.85771 | AQ12: 8.1024 | AR12: 14.03625 | AS12: 9.27437 | AT12: 8.85259 | AU12: 11.0246 | AV12: 11.3727 | AW12: 9.98519 | AX12: 9.62887 | AY12: 12.39826 | AZ12: 9.96083 | BA12: 9.32773 | BB12: 10.79865 | BC12: 9.31693 | BD12: 10.00011 | BF12: 125 | BG12: 6.61392 | BH12: 6.3904 | BI12: 6.74276 | BJ12: 6.90889 | BK12: 6.64048 | BL12: 6.76165 | BM12: 6.67346 | BN12: 6.60282 | BO12: 6.62025 | BP12: 6.76257 | BQ12: 6.59482 | BR12: 6.60954 | BS12: 6.65987 | BT12: 7.02043 | BU12: 6.51279 | BV12: 6.69408 | BW12: 6.64499 | BX12: 6.47144 | BY12: 6.82018 | BZ12: 6.57658
N13: 132 | O13: 74.60974 | P13: 75.6188 | Q13: 75.00851 | R13: 75.30984 | S13: 75.30227 | T13: 75.07176 | U13: 75.78744 | V13: 75.64402 | W13: 75.53632 | X13: 75.51907 | Y13: 74.31661 | Z13: 75.52169 | AA13: 75.49595 | AB13: 74.93256 | AC13: 75.75263 | AD13: 74.93046 | AE13: 75.41011 | AF13: 75.66943 | AG13: 74.7059 | AH13: 75.29169 | AJ13: 132 | AK13: 8.58508 | AL13: 14.27537 | AM13: 11.86884 | AN13: 8.75362 | AO13: 8.64056 | AP13: 8.76125 | AQ13: 8.02556 | AR13: 13.75214 | AS13: 9.15991 | AT13: 8.75514 | AU13: 10.82832 | AV13: 11.14027 | AW13: 9.86528 | AX13: 9.55704 | AY13: 12.2622 | AZ13: 9.7751 | BA13: 9.1449 | BB13: 10.68837 | BC13: 9.17931 | BD13: 9.83358 | BF13: 132 | BG13: 6.65796 | BH13: 6.43844 | BI13: 6.78693 | BJ13: 6.93843 | BK13: 6.68641 | BL13: 6.80159 | BM13: 6.71536 | BN13: 6.64762 | BO13: 6.66513 | BP13: 6.80315 | BQ13: 6.63936 | BR13: 6.6402 | BS13: 6.70487 | BT13: 7.03287 | BU13: 6.55754 | BV13: 6.63902 | BW13: 6.68894 | BX13: 6.51748 | BY13: 6.86386 | BZ13: 6.61953
N14: 140 | O14: 76.13108 | P14: 76.87085 | Q14: 76.28845 | R14: 76.57441 | S14: 76.63531 | T14: 76.34706 | U14: 76.99312 | V14: 76.8466 | W14: 76.81991 | X14: 76.76417 | Y14: 75.55309 | Z14: 76.81826 | AA14: 76.77804 | AB14: 76.36867 | AC14: 77.09451 | AD14: 76.30631 | AE14: 76.75585 | AF14: 76.91866 | AG14: 76.03859 | AH14: 76.61924 | AJ14: 140 | AK14: 8.40304 | AL14: 13.073 | AM14: 11.58309 | AN14: 8.65837 | AO14: 8.46471 | AP14: 8.56825 | AQ14: 7.98113 | AR14: 13.51601 | AS14: 9.03322 | AT14: 8.63002 | AU14: 10.64274 | AV14: 10.90337 | AW14: 9.72603 | AX14: 9.38196 | AY14: 12.04529 | AZ14: 9.56373 | BA14: 9.01591 | BB14: 10.53662 | BC14: 9.05047 | BD14: 9.65404 | BF14: 140 | BG14: 6.70196 | BH14: 6.48429 | BI14: 6.82932 | BJ14: 6.96719 | BK14: 6.73025 | BL14: 6.83973 | BM14: 6.75735 | BN14: 6.69091 | BO14: 6.70985 | BP14: 6.84524 | BQ14: 6.68225 | BR14: 6.68013 | BS14: 6.74973 | BT14: 7.07155 | BU14: 6.60177 | BV14: 6.70131 | BW14: 6.73225 | BX14: 6.56229 | BY14: 6.90563 | BZ14: 6.66142
N15: 150 | O15: 77.51077 | P15: 78.15268 | Q15: 77.63348 | R15: 77.88644 | S15: 77.98658 | T15: 77.70801 | U15: 78.32453 | V15: 78.09441 | W15: 78.15798 | X15: 78.04037 | Y15: 76.98554 | Z15: 78.12898 | AA15: 78.05178 | AB15: 77.70931 | AC15: 78.39507 | AD15: 77.68339 | AE15: 78.09992 | AF15: 78.27418 | AG15: 77.38166 | AH15: 77.9235 | AJ15: 150 | AK15: 8.22385 | AL15: 11.76334 | AM15: 11.13521 | AN15: 8.68384 | AO15: 8.25917 | AP15: 8.3119 | AQ15: 7.79188 | AR15: 13.22378 | AS15: 8.49241 | AT15: 8.4815 | AU15: 10.35347 | AV15: 10.51395 | AW15: 9.12702 | AX15: 9.16286 | AY15: 11.7067 | AZ15: 9.20547 | BA15: 8.52602 | BB15: 10.37377 | BC15: 8.86262 | BD15: 9.3687 | BF15: 150 | BG15: 6.74726 | BH15: 6.53194 | BI15: 6.87423 | BJ15: 7.00325 | BK15: 6.77743 | BL15: 6.87899 | BM15: 6.80903 | BN15: 6.73786 | BO15: 6.75679 | BP15: 6.88739 | BQ15: 6.72927 | BR15: 6.72322 | BS15: 6.79632 | BT15: 7.11016 | BU15: 6.64904 | BV15: 6.72601 | BW15: 6.77778 | BX15: 6.60939 | BY15: 6.95162 | BZ15: 6.70681
N16: 160 | O16: 78.92601 | P16: 79.4617 | Q16: 78.96627 | R16: 79.20291 | S16: 79.25395 | T16: 79.07124 | U16: 79.64311 | V16: 79.40204 | W16: 79.48799 | X16: 79.3422 | Y16: 78.36797 | Z16: 79.49007 | AA16: 79.37628 | AB16: 79.06792 | AC16: 79.7346 | AD16: 79.04469 | AE16: 79.39426 | AF16: 79.59616 | AG16: 78.72146 | AH16: 79.21911 | AJ16: 160 | AK16: 8.03415 | AL16: 10.702 | AM16: 9.60047 | AN16: 8.47644 | AO16: 8.19807 | AP16: 8.18227 | AQ16: 7.64701 | AR16: 12.84756 | AS16: 8.36199 | AT16: 8.37465 | AU16: 10.09612 | AV16: 10.18907 | AW16: 8.96211 | AX16: 9.0012 | AY16: 11.35633 | AZ16: 8.93495 | BA16: 8.34294 | BB16: 10.20234 | BC16: 8.7213 | BD16: 9.22377 | BF16: 160 | BG16: 6.78557 | BH16: 6.57146 | BI16: 6.91267 | BJ16: 7.0391 | BK16: 6.81692 | BL16: 6.91212 | BM16: 6.86046 | BN16: 6.77744 | BO16: 6.79764 | BP16: 6.92543 | BQ16: 6.76906 | BR16: 6.76413 | BS16: 6.8365 | BT16: 7.1468 | BU16: 6.68817 | BV16: 6.77913 | BW16: 6.81537 | BX16: 6.64868 | BY16: 6.98951 | BZ16: 6.74521
N17: 170 | O17: 80.29276 | P17: 80.74009 | Q17: 80.26962 | R17: 80.52102 | S17: 80.55421 | T17: 80.38233 | U17: 80.93151 | V17: 80.68318 | W17: 80.7941 | X17: 80.65125 | Y17: 79.73555 | Z17: 80.814 | AA17: 80.72223 | AB17: 80.42567 | AC17: 81.06414 | AD17: 80.392 | AE17: 80.65333 | AF17: 80.91427 | AG17: 80.02874 | AH17: 80.53055 | AJ17: 170 | AK17: 7.88608 | AL17: 9.97865 | AM17: 9.33758 | AN17: 8.44072 | AO17: 8.15334 | AP17: 8.09888 | AQ17: 7.60589 | AR17: 12.11727 | AS17: 8.27424 | AT17: 8.34454 | AU17: 9.99031 | AV17: 9.95483 | AW17: 8.89171 | AX17: 9.0623 | AY17: 10.93329 | AZ17: 8.81882 | BA17: 8.28633 | BB17: 10.08611 | BC17: 8.6379 | BD17: 9.14655 | BF17: 170 | BG17: 6.81965 | BH17: 6.60629 | BI17: 6.94454 | BJ17: 7.0726 | BK17: 6.84943 | BL17: 6.94014 | BM17: 6.89049 | BN17: 6.80999 | BO17: 6.83016 | BP17: 6.95672 | BQ17: 6.80256 | BR17: 6.79257 | BS17: 6.87089 | BT17: 7.16474 | BU17: 6.72107 | BV17: 6.82094 | BW17: 6.84764 | BX17: 6.68227 | BY17: 7.02139 | BZ17: 6.77774
N18: 180 | O18: 81.5761 | P18: 81.98243 | Q18: 81.5395 | R18: 81.7408 | S18: 81.77465 | T18: 81.66254 | U18: 82.17534 | V18: 81.8998 | W18: 82.04526 | X18: 81.8765 | Y18: 81.08719 | Z18: 82.01983 | AA18: 81.97962 | AB18: 81.71615 | AC18: 82.27863 | AD18: 81.63675 | AE18: 81.88962 | AF18: 82.12032 | AG18: 81.246 | AH18: 81.78527 | AJ18: 180 | AK18: 7.88269 | AL18: 9.75659 | AM18: 9.27907 | AN18: 8.47338 | AO18: 8.17072 | AP18: 8.06531 | AQ18: 7.63843 | AR18: 12.03794 | AS18: 8.21929 | AT18: 8.44344 | AU18: 9.92734 | AV18: 9.85033 | AW18: 8.9253 | AX18: 9.42461 | AY18: 10.91578 | AZ18: 8.81351 | BA18: 8.31828 | BB18: 10.03054 | BC18: 8.66042 | BD18: 9.1584 | BF18: 180 | BG18: 6.84896 | BH18: 6.63557 | BI18: 6.97188 | BJ18: 7.11094 | BK18: 6.87808 | BL18: 6.9651 | BM18: 6.91046 | BN18: 6.8384 | BO18: 6.85714 | BP18: 6.98497 | BQ18: 6.83111 | BR18: 6.80599 | BS18: 6.89933 | BT18: 7.15835 | BU18: 6.74884 | BV18: 6.86317 | BW18: 6.87507 | BX18: 6.71153 | BY18: 7.04846 | BZ18: 6.80538
L19: Limit | N19: 190 | O19: 82.84238 | P19: 83.18317 | Q19: 82.81918 | R19: 82.97541 | S19: 83.00794 | T19: 82.89832 | U19: 83.42211 | V19: 83.12229 | W19: 83.24934 | X19: 83.09752 | Y19: 82.40837 | Z19: 83.22394 | AA19: 83.24621 | AB19: 83.0099 | AC19: 83.49019 | AD19: 82.89069 | AE19: 83.09528 | AF19: 83.33944 | AG19: 82.43092 | AH19: 82.97409 | AJ19: 190 | AK19: 7.94643 | AL19: 9.68004 | AM19: 9.31971 | AN19: 8.57511 | AO19: 8.27105 | AP19: 8.09448 | AQ19: 7.74408 | AR19: 12.01591 | AS19: 8.09843 | AT19: 8.60026 | AU19: 9.88154 | AV19: 9.67694 | AW19: 9.04267 | AX19: 9.58126 | AY19: 10.97027 | AZ19: 8.93331 | BA19: 8.43954 | BB19: 10.08371 | BC19: 8.761 | BD19: 9.26778 | BF19: 190 | BG19: 6.87541 | BH19: 6.66167 | BI19: 6.99582 | BJ19: 7.12875 | BK19: 6.90403 | BL19: 6.98619 | BM19: 6.93303 | BN19: 6.86335 | BO19: 6.88213 | BP19: 7.0095 | BQ19: 6.85731 | BR19: 6.7818 | BS19: 6.92481 | BT19: 7.1762 | BU19: 6.77414 | BV19: 6.94336 | BW19: 6.89952 | BX19: 6.73777 | BY19: 7.07324 | BZ19: 6.82955
K20: 100 | L20: 25 | N20: 200 | O20: 84.02269 | P20: 84.35227 | Q20: 84.02019 | R20: 84.14766 | S20: 84.17748 | T20: 84.07596 | U20: 84.59446 | V20: 84.27905 | W20: 84.39696 | X20: 84.26108 | Y20: 83.61587 | Z20: 84.38493 | AA20: 84.43002 | AB20: 84.20562 | AC20: 84.64477 | AD20: 84.0905 | AE20: 84.26057 | AF20: 84.5006 | AG20: 83.57032 | AH20: 84.14276 | AJ20: 200 | AK20: 8.04867 | AL20: 9.69986 | AM20: 9.42998 | AN20: 8.77936 | AO20: 8.43459 | AP20: 8.26763 | AQ20: 7.92933 | AR20: 12.06724 | AS20: 8.09628 | AT20: 8.82938 | AU20: 10.12069 | AV20: 9.74608 | AW20: 9.24885 | AX20: 9.82327 | AY20: 11.10223 | AZ20: 9.09439 | BA20: 8.618 | BB20: 10.18966 | BC20: 8.93199 | BD20: 9.427 | BF20: 200 | BG20: 6.89892 | BH20: 6.68399 | BI20: 7.01742 | BJ20: 7.15994 | BK20: 6.92662 | BL20: 7.00474 | BM20: 6.95314 | BN20: 6.88497 | BO20: 6.90614 | BP20: 7.0303 | BQ20: 6.87945 | BR20: 6.78863 | BS20: 6.94814 | BT20: 7.16831 | BU20: 6.79686 | BV20: 6.95886 | BW20: 6.92209 | BX20: 6.76126 | BY20: 7.09485 | BZ20: 6.85075
K21: 200 | L21: 22 | N21: 212 | O21: 85.13827 | P21: 85.45772 | Q21: 85.15184 | R21: 85.26269 | S21: 85.29044 | T21: 85.18764 | U21: 85.70971 | V21: 85.38345 | W21: 85.49272 | X21: 85.37208 | Y21: 84.7573 | Z21: 85.49171 | AA21: 85.53004 | AB21: 85.31126 | AC21: 85.72403 | AD21: 85.20934 | AE21: 85.37808 | AF21: 85.60389 | AG21: 84.66281 | AH21: 85.23461 | AJ21: 212 | AK21: 8.26502 | AL21: 9.98685 | AM21: 9.62024 | AN21: 9.12301 | AO21: 8.76476 | AP21: 8.52326 | AQ21: 8.27794 | AR21: 12.31887 | AS21: 8.31563 | AT21: 9.19476 | AU21: 10.47616 | AV21: 9.82567 | AW21: 9.68428 | AX21: 10.2555 | AY21: 11.34918 | AZ21: 9.32528 | BA21: 8.97573 | BB21: 10.42134 | BC21: 9.28198 | BD21: 9.72931 | BF21: 212 | BG21: 6.92328 | BH21: 6.70907 | BI21: 7.03919 | BJ21: 7.16281 | BK21: 6.95008 | BL21: 7.02581 | BM21: 6.97648 | BN21: 6.90708 | BO21: 6.9308 | BP21: 7.05288 | BQ21: 6.90322 | BR21: 6.83168 | BS21: 6.97199 | BT21: 7.04464 | BU21: 6.82098 | BV21: 6.99476 | BW21: 6.94451 | BX21: 6.78563 | BY21: 7.1176 | BZ21: 6.87351
